<?xml version="1.0" encoding="utf-8"?>
<!-- This URDF was automatically created by SolidWorks to URDF Exporter! Originally created by Stephen Brawner (brawner@gmail.com) 
     Commit Version: 1.6.0-4-g7f85cfe  Build Version: 1.6.7995.38578
     For more information, please see http://wiki.ros.org/sw_urdf_exporter -->
<robot
  name="URDF_Humanoid_legs_V6">
  <link
    name="base_link">
    <inertial>
      <origin
        xyz="-1.20525189667888E-17 -0.00116687807024146 9.70352431595157E-19"
        rpy="0 0 0" />
      <mass
        value="6.0" />
      <inertia
        ixx="6.362e-05"
        ixy="-3.21e-08"
        ixz="-1.346e-07"
        iyy="5.211e-05"
        iyz="5.765e-08"
        izz="6.365e-05" />
    </inertial>
    <visual>
      <origin
        xyz="0 0 0"
        rpy="0 0 0" />
      <geometry>
        <mesh
          filename="package://URDF_Humanoid_legs_V6/meshes/base_link.STL" />
      </geometry>
      <material
        name="">
        <color
          rgba="1 1 1 1" />
      </material>
    </visual>
    <collision>
      <origin
        xyz="0 0 0"
        rpy="0 0 0" />
      <geometry>
        <mesh
          filename="package://URDF_Humanoid_legs_V6/meshes/base_link.STL" />
      </geometry>
    </collision>
  </link>
  <link
    name="pelvis_link">
    <inertial>
      <origin
        xyz="0.000246658721500989 -0.0263650300485569 0.0262415333889873"
        rpy="0 0 0" />
      <mass
        value="0.76" />
      <inertia
        ixx="2.48084693670909E-05"
        ixy="9.13293468847299E-11"
        ixz="7.12543825132061E-11"
        iyy="8.77655830853484E-05"
        iyz="2.89164646463755E-08"
        izz="8.92384807900428E-05" />
    </inertial>
    <visual>
      <origin
        xyz="0 0 0"
        rpy="0 0 0" />
      <geometry>
        <mesh
          filename="package://URDF_Humanoid_legs_V6/meshes/pelvis_link.STL" />
      </geometry>
      <material
        name="">
        <color
          rgba="0.792156862745098 0.819607843137255 0.933333333333333 1" />
      </material>
    </visual>
    <collision>
      <origin
        xyz="0 0 0"
        rpy="0 0 0" />
      <geometry>
        <mesh
          filename="package://URDF_Humanoid_legs_V6/meshes/pelvis_link.STL" />
      </geometry>
    </collision>
  </link>
  <joint
    name="pelvis_link"
    type="revolute">
    <origin
      xyz="0 0.04055 -0.095"
      rpy="1.5708 0 0" />
    <parent
      link="base_link" />
    <child
      link="pelvis_link" />
    <axis
      xyz="0 0 1" />
    <limit
      lower="-1.6"
      upper="1.6"
      effort="0"
      velocity="0" />
  </joint>
  <link
    name="RHIPp">
    <inertial>
      <origin
        xyz="0.0176283564301995 -0.0127769986297945 0.0137529492155175"
        rpy="0 0 0" />
      <mass
        value="0.08647" />
      <inertia
        ixx="1.36413523750568E-05"
        ixy="1.54973998562193E-06"
        ixz="2.89382212554602E-06"
        iyy="1.29568407083375E-05"
        iyz="-3.52554248132011E-06"
        izz="5.98007315980272E-06" />
    </inertial>
    <visual>
      <origin
        xyz="0 0 0"
        rpy="0 0 0" />
      <geometry>
        <mesh
          filename="package://URDF_Humanoid_legs_V6/meshes/RHIPp.STL" />
      </geometry>
      <material
        name="">
        <color
          rgba="0.866666666666667 0.909803921568627 1 1" />
      </material>
    </visual>
    <collision>
      <origin
        xyz="0 0 0"
        rpy="0 0 0" />
      <geometry>
        <mesh
          filename="package://URDF_Humanoid_legs_V6/meshes/RHIPp.STL" />
      </geometry>
    </collision>
  </link>
  <joint
    name="RHIPp"
    type="revolute">
    <origin
      xyz="-0.0899 -0.027 0.04725"
      rpy="0.54799 0 0" />
    <parent
      link="pelvis_link" />
    <child
      link="RHIPp" />
    <axis
      xyz="1 0 0" />
    <limit
      lower="-3.1"
      upper="0.79"
      effort="0"
      velocity="0" />
  </joint>
  <link
    name="RHIPy">
    <inertial>
      <origin
        xyz="-0.00372207331369191 -0.0312537397608706 0.0232286445316926"
        rpy="0 0 0" />
      <mass
        value="0.01938" />
      <inertia
        ixx="5.48250308299681E-06"
        ixy="-1.4470005450136E-06"
        ixz="-8.08508822369013E-07"
        iyy="3.9832749758332E-06"
        iyz="-1.49821709259362E-06"
        izz="4.01650939723747E-06" />
    </inertial>
    <visual>
      <origin
        xyz="0 0 0"
        rpy="0 0 0" />
      <geometry>
        <mesh
          filename="package://URDF_Humanoid_legs_V6/meshes/RHIPy.STL" />
      </geometry>
      <material
        name="">
        <color
          rgba="1 1 1 1" />
      </material>
    </visual>
    <collision>
      <origin
        xyz="0 0 0"
        rpy="0 0 0" />
      <geometry>
        <mesh
          filename="package://URDF_Humanoid_legs_V6/meshes/RHIPy.STL" />
      </geometry>
    </collision>
  </link>
  <joint
    name="RHIPy"
    type="revolute">
    <origin
      xyz="0.0013406 0.00058603 0.00096017"
      rpy="0 0 0" />
    <parent
      link="RHIPp" />
    <child
      link="RHIPy" />
    <axis
      xyz="0 0.52097 0.85357" />
    <limit
      lower="-1.6"
      upper="0.7"
      effort="0"
      velocity="0" />
  </joint>
  <link
    name="RHIPr">
    <inertial>
      <origin
        xyz="-0.00852993209921661 -0.00430333806534099 0.0409064137132635"
        rpy="0 0 0" />
      <mass
        value="0.21474" />
      <inertia
        ixx="3.20005325214886E-05"
        ixy="-2.13313819385782E-07"
        ixz="-2.70133661582282E-06"
        iyy="2.93884957981145E-05"
        iyz="-2.31062770446574E-07"
        izz="9.4482341452486E-06" />
    </inertial>
    <visual>
      <origin
        xyz="0 0 0"
        rpy="0 0 0" />
      <geometry>
        <mesh
          filename="package://URDF_Humanoid_legs_V6/meshes/RHIPr.STL" />
      </geometry>
      <material
        name="">
        <color
          rgba="1 1 1 1" />
      </material>
    </visual>
    <collision>
      <origin
        xyz="0 0 0"
        rpy="0 0 0" />
      <geometry>
        <mesh
          filename="package://URDF_Humanoid_legs_V6/meshes/RHIPr.STL" />
      </geometry>
    </collision>
  </link>
  <joint
    name="RHIPr"
    type="revolute">
    <origin
      xyz="-0.0019151 -0.17144 0.10276"
      rpy="2.1188 0 3.1416" />
    <parent
      link="RHIPy" />
    <child
      link="RHIPr" />
    <axis
      xyz="0 0 1" />
    <limit
      lower="-1.7"
      upper="0.52"
      effort="0"
      velocity="0" />
  </joint>
  <link
    name="RKNEEp">
    <inertial>
      <origin
        xyz="-0.0208592225572688 -0.0628859174153643 0.0364105609882808"
        rpy="0 0 0" />
      <mass
        value="0.14365" />
      <inertia
        ixx="6.25685418392409E-05"
        ixy="-9.75526866469471E-07"
        ixz="5.53113397277369E-07"
        iyy="1.79827988662239E-05"
        iyz="2.36965661459174E-05"
        izz="4.8546073873039E-05" />
    </inertial>
    <visual>
      <origin
        xyz="0 0 0"
        rpy="0 0 0" />
      <geometry>
        <mesh
          filename="package://URDF_Humanoid_legs_V6/meshes/RKNEEp.STL" />
      </geometry>
      <material
        name="">
        <color
          rgba="1 1 1 1" />
      </material>
    </visual>
    <collision>
      <origin
        xyz="0 0 0"
        rpy="0 0 0" />
      <geometry>
        <mesh
          filename="package://URDF_Humanoid_legs_V6/meshes/RKNEEp.STL" />
      </geometry>
    </collision>
  </link>
  <joint
    name="RKNEEp"
    type="revolute">
    <origin
      xyz="-0.0145 0.0005 0"
      rpy="2.0938 -0.031615 -3.1045" />
    <parent
      link="RHIPr" />
    <child
      link="RKNEEp" />
    <axis
      xyz="0.99881 -0.0088645 0.047869" />
    <limit
      lower="-0.79"
      upper="2.6"
      effort="0"
      velocity="0" />
  </joint>
  <link
    name="RANKLEp">
    <inertial>
      <origin
        xyz="0.000499998150396253 1.84960360916087E-09 -0.00486658078174895"
        rpy="0 0 0" />
      <mass
        value="0.00592" />
      <inertia
        ixx="3.77945222686951E-08"
        ixy="-6.92461213790612E-21"
        ixz="6.88284860579712E-21"
        iyy="3.77945222686952E-08"
        iyz="-6.87032460696589E-21"
        izz="3.77945222686951E-08" />
    </inertial>
    <visual>
      <origin
        xyz="0 0 0"
        rpy="0 0 0" />
      <geometry>
        <mesh
          filename="package://URDF_Humanoid_legs_V6/meshes/RANKLEp.STL" />
      </geometry>
      <material
        name="">
        <color
          rgba="0.866666666666667 0.909803921568627 1 1" />
      </material>
    </visual>
    <collision>
      <origin
        xyz="0 0 0"
        rpy="0 0 0" />
      <geometry>
        <mesh
          filename="package://URDF_Humanoid_legs_V6/meshes/RANKLEp.STL" />
      </geometry>
    </collision>
  </link>
  <joint
    name="RANKLEp"
    type="revolute">
    <origin
      xyz="-0.020463 -0.17739 0.10166"
      rpy="0.0956 1.0455 -1.4969" />
    <parent
      link="RKNEEp" />
    <child
      link="RANKLEp" />
    <axis
      xyz="0 1 0" />
    <limit
      lower="-1.4"
      upper="1.4"
      effort="0"
      velocity="0" />
  </joint>
  <link
    name="RANKLEy">
    <inertial>
      <origin
        xyz="2.18288026543334E-11 0.0405307343912282 0.021533981746651"
        rpy="0 0 0" />
      <mass
        value="0.14984" />
      <inertia
        ixx="8.38514534857727E-05"
        ixy="5.00798540029232E-15"
        ixz="3.65941089800678E-15"
        iyy="1.37440917358923E-05"
        iyz="-1.13165479474976E-08"
        izz="9.70905380762813E-05" />
    </inertial>
    <visual>
      <origin
        xyz="0 0 0"
        rpy="0 0 0" />
      <geometry>
        <mesh
          filename="package://URDF_Humanoid_legs_V6/meshes/RANKLEy.STL" />
      </geometry>
      <material
        name="">
        <color
          rgba="1 1 1 1" />
      </material>
    </visual>
    <collision>
      <origin
        xyz="0 0 0"
        rpy="0 0 0" />
      <geometry>
        <mesh
          filename="package://URDF_Humanoid_legs_V6/meshes/RANKLEy.STL" />
      </geometry>
    </collision>
  </link>
  <joint
    name="RANKLEy"
    type="revolute">
    <origin
      xyz="0 0 -0.005"
      rpy="0 0 1.5708" />
    <parent
      link="RANKLEp" />
    <child
      link="RANKLEy" />
    <axis
      xyz="0 1 0" />
    <limit
      lower="-0.52"
      upper="0.52"
      effort="0"
      velocity="0" />
  </joint>
  <link
    name="LHIPp">
    <inertial>
      <origin
        xyz="0.0050657735192334 0.0175468312094787 0.0180828986022031"
        rpy="0 0 0" />
      <mass
        value="0.08647" />
      <inertia
        ixx="4.47354437359763E-06"
        ixy="2.66504529496216E-06"
        ixz="-1.42372121100556E-06"
        iyy="1.38696354566827E-05"
        iyz="4.37730445482361E-08"
        izz="1.42350863513426E-05" />
    </inertial>
    <visual>
      <origin
        xyz="0 0 0"
        rpy="0 0 0" />
      <geometry>
        <mesh
          filename="package://URDF_Humanoid_legs_V6/meshes/LHIPp.STL" />
      </geometry>
      <material
        name="">
        <color
          rgba="0.866666666666667 0.909803921568627 1 1" />
      </material>
    </visual>
    <collision>
      <origin
        xyz="0 0 0"
        rpy="0 0 0" />
      <geometry>
        <mesh
          filename="package://URDF_Humanoid_legs_V6/meshes/LHIPp.STL" />
      </geometry>
    </collision>
  </link>
  <joint
    name="LHIPp"
    type="revolute">
    <origin
      xyz="0.0899 -0.027 0.04725"
      rpy="1.5708 -1.5708 0" />
    <parent
      link="pelvis_link" />
    <child
      link="LHIPp" />
    <axis
      xyz="0 -1 0" />
    <limit
      lower="-3.1"
      upper="0.79"
      effort="0"
      velocity="0" />
  </joint>
  <link
    name="LHIPy">
    <inertial>
      <origin
        xyz="0.000407510080640483 -0.00263808681897358 0.0398992326314333"
        rpy="0 0 0" />
      <mass
        value="0.01938" />
      <inertia
        ixx="1.56132626802381E-05"
        ixy="-7.07458995414408E-06"
        ixz="2.90668462732438E-06"
        iyy="3.24353194636071E-05"
        iyz="4.47644236574541E-06"
        izz="3.17288201922621E-05" />
    </inertial>
    <visual>
      <origin
        xyz="0 0 0"
        rpy="0 0 0" />
      <geometry>
        <mesh
          filename="package://URDF_Humanoid_legs_V6/meshes/LHIPy.STL" />
      </geometry>
      <material
        name="">
        <color
          rgba="0.866666666666667 0.909803921568627 1 1" />
      </material>
    </visual>
    <collision>
      <origin
        xyz="0 0 0"
        rpy="0 0 0" />
      <geometry>
        <mesh
          filename="package://URDF_Humanoid_legs_V6/meshes/LHIPy.STL" />
      </geometry>
    </collision>
  </link>
  <joint
    name="LHIPy"
    type="revolute">
    <origin
      xyz="0 0 0"
      rpy="0 0 0" />
    <parent
      link="LHIPp" />
    <child
      link="LHIPy" />
    <axis
      xyz="1 0 0" />
    <limit
      lower="-0.7"
      upper="1.6"
      effort="0"
      velocity="0" />
  </joint>
  <link
    name="LHIPr">
    <inertial>
      <origin
        xyz="-0.00858602166340268 -0.00470614629897966 -0.0410634654031223"
        rpy="0 0 0" />
      <mass
        value="0.21474" />
      <inertia
        ixx="3.19983815933138E-05"
        ixy="-2.13602157790844E-07"
        ixz="2.70146580700876E-06"
        iyy="2.93873073304588E-05"
        iyz="2.28332340691089E-07"
        izz="9.44705170658347E-06" />
    </inertial>
    <visual>
      <origin
        xyz="0 0 0"
        rpy="0 0 0" />
      <geometry>
        <mesh
          filename="package://URDF_Humanoid_legs_V6/meshes/LHIPr.STL" />
      </geometry>
      <material
        name="">
        <color
          rgba="1 1 1 1" />
      </material>
    </visual>
    <collision>
      <origin
        xyz="0 0 0"
        rpy="0 0 0" />
      <geometry>
        <mesh
          filename="package://URDF_Humanoid_legs_V6/meshes/LHIPr.STL" />
      </geometry>
    </collision>
  </link>
  <joint
    name="LHIPr"
    type="revolute">
    <origin
      xyz="-0.00048209 -0.00057453 0.2"
      rpy="0 0 -1.5708" />
    <parent
      link="LHIPy" />
    <child
      link="LHIPr" />
    <axis
      xyz="0 0 -1" />
    <limit
      lower="-0.52"
      upper="1.7"
      effort="0"
      velocity="0" />
  </joint>
  <link
    name="LKNEEp">
    <inertial>
      <origin
        xyz="0.0198943587515279 0.00129513598691519 0.0714650508892875"
        rpy="0 0 0" />
      <mass
        value="0.14365" />
      <inertia
        ixx="0.000169233199863093"
        ixy="2.4878093513664E-08"
        ixz="1.74423877794731E-06"
        iyy="0.000165987468944694"
        iyz="3.70937004397106E-06"
        izz="1.38660391420083E-05" />
    </inertial>
    <visual>
      <origin
        xyz="0 0 0"
        rpy="0 0 0" />
      <geometry>
        <mesh
          filename="package://URDF_Humanoid_legs_V6/meshes/LKNEEp.STL" />
      </geometry>
      <material
        name="">
        <color
          rgba="0.866666666666667 0.909803921568627 1 1" />
      </material>
    </visual>
    <collision>
      <origin
        xyz="0 0 0"
        rpy="0 0 0" />
      <geometry>
        <mesh
          filename="package://URDF_Humanoid_legs_V6/meshes/LKNEEp.STL" />
      </geometry>
    </collision>
  </link>
  <joint
    name="LKNEEp"
    type="revolute">
    <origin
      xyz="-0.0152 0 0"
      rpy="0 0 0" />
    <parent
      link="LHIPr" />
    <child
      link="LKNEEp" />
    <axis
      xyz="-1 0 0" />
    <limit
      lower="-2.6"
      upper="0.79"
      effort="0"
      velocity="0" />
  </joint>
  <link
    name="LANKLEp">
    <inertial>
      <origin
        xyz="-1.8496038034499E-09 -1.84960471938389E-09 0.00500000184959861"
        rpy="0 0 0" />
      <mass
        value="0.00592" />
      <inertia
        ixx="3.77945222686952E-08"
        ixy="6.93648859813129E-21"
        ixz="-6.87547050268817E-21"
        iyy="3.77945222686952E-08"
        iyz="-6.92699765262999E-21"
        izz="3.77945222686952E-08" />
    </inertial>
    <visual>
      <origin
        xyz="0 0 0"
        rpy="0 0 0" />
      <geometry>
        <mesh
          filename="package://URDF_Humanoid_legs_V6/meshes/LANKLEp.STL" />
      </geometry>
      <material
        name="">
        <color
          rgba="0.866666666666667 0.909803921568627 1 1" />
      </material>
    </visual>
    <collision>
      <origin
        xyz="0 0 0"
        rpy="0 0 0" />
      <geometry>
        <mesh
          filename="package://URDF_Humanoid_legs_V6/meshes/LANKLEp.STL" />
      </geometry>
    </collision>
  </link>
  <joint
    name="LANKLEp"
    type="revolute">
    <origin
      xyz="0.0152 0.005 0.2"
      rpy="1.5708 1.5708 0" />
    <parent
      link="LKNEEp" />
    <child
      link="LANKLEp" />
    <axis
      xyz="0 -1 0" />
    <limit
      lower="-1.4"
      upper="1.4"
      effort="0"
      velocity="0" />
  </joint>
  <link
    name="LANKLEy">
    <inertial>
      <origin
        xyz="2.32737162875196E-11 0.0376072027848135 -0.0235825366832185"
        rpy="0 0 0" />
      <mass
        value="0.14984" />
      <inertia
        ixx="8.37067999506024E-05"
        ixy="2.2030144941654E-14"
        ixz="-4.78040252207365E-15"
        iyy="1.38141738118883E-05"
        iyz="4.21765319002781E-06"
        izz="9.66362481803396E-05" />
    </inertial>
    <visual>
      <origin
        xyz="0 0 0"
        rpy="0 0 0" />
      <geometry>
        <mesh
          filename="package://URDF_Humanoid_legs_V6/meshes/LANKLEy.STL" />
      </geometry>
      <material
        name="">
        <color
          rgba="1 1 1 1" />
      </material>
    </visual>
    <collision>
      <origin
        xyz="0 0 0"
        rpy="0 0 0" />
      <geometry>
        <mesh
          filename="package://URDF_Humanoid_legs_V6/meshes/LANKLEy.STL" />
      </geometry>
    </collision>
  </link>
  <joint
    name="LANKLEy"
    type="revolute">
    <origin
      xyz="0 0 0"
      rpy="-1.5202 0 -1.5708" />
    <parent
      link="LANKLEp" />
    <child
      link="LANKLEy" />
    <axis
      xyz="0 -0.99872 0.050592" />
    <limit
      lower="-0.523"
      upper="0.523"
      effort="0"
      velocity="0" />
  </joint>
</robot>