<?xml version="1.0" encoding="utf-8"?>
<!-- This URDF was automatically created by SolidWorks to URDF Exporter! Originally created by Stephen Brawner (brawner@gmail.com) 
     Commit Version: 1.6.0-4-g7f85cfe  Build Version: 1.6.7995.38578
     For more information, please see http://wiki.ros.org/sw_urdf_exporter -->
<robot
  name="URDF_Forquad_V3">
  <link
    name="base_link">
    <inertial>
      <origin
        xyz="-0.00176945614024935 -0.0327834476084241 0.0843845449556888"
        rpy="0 0 0" />
      <mass
        value="6.76" />
      <inertia
        ixx="0.0015762882875626"
        ixy="8.22091029760431E-09"
        ixz="7.41870738272031E-09"
        iyy="0.00227078630816896"
        iyz="-6.08362868343035E-05"
        izz="0.000860974045264762" />
    </inertial>
    <visual>
      <origin
        xyz="0 0 0"
        rpy="0 0 0" />
      <geometry>
        <mesh
          filename="package://URDF_Forquad_V3/meshes/base_link.STL" />
      </geometry>
      <material
        name="">
        <color
          rgba="0.792156862745098 0.819607843137255 0.933333333333333 1" />
      </material>
    </visual>
    <collision>
      <origin
        xyz="0 0 0"
        rpy="0 0 0" />
      <geometry>
        <mesh
          filename="package://URDF_Forquad_V3/meshes/base_link.STL" />
      </geometry>
    </collision>
  </link>
  <link
    name="FL_Hip_pitch">
    <inertial>
      <origin
        xyz="0.00603741315673325 0.0192625721793669 0.0180424979701229"
        rpy="0 0 0" />
      <mass
        value="0.04037" />
      <inertia
        ixx="1.7433970507819E-06"
        ixy="1.2256529920422E-06"
        ixz="-5.24677749412567E-07"
        iyy="5.02166848316155E-06"
        iyz="4.32112337565604E-08"
        izz="5.30095897072275E-06" />
    </inertial>
    <visual>
      <origin
        xyz="0 0 0"
        rpy="0 0 0" />
      <geometry>
        <mesh
          filename="package://URDF_Forquad_V3/meshes/FL_Hip_pitch.STL" />
      </geometry>
      <material
        name="">
        <color
          rgba="0.792156862745098 0.819607843137255 0.933333333333333 1" />
      </material>
    </visual>
    <collision>
      <origin
        xyz="0 0 0"
        rpy="0 0 0" />
      <geometry>
        <mesh
          filename="package://URDF_Forquad_V3/meshes/FL_Hip_pitch.STL" />
      </geometry>
    </collision>
  </link>
  <joint
    name="FL_Hip_pitch"
    type="revolute">
    <origin
      xyz="0.1683 -0.04325 0.15"
      rpy="3.1416 0 -1.5708" />
    <parent
      link="base_link" />
    <child
      link="FL_Hip_pitch" />
    <axis
      xyz="0 1 0" />
    <limit
      lower="-0.785"
      upper="3.14"
      effort="0"
      velocity="0" />
  </joint>
  <link
    name="FL_Hip_yaw">
    <inertial>
      <origin
        xyz="0.00434315401862641 0.00880065015274928 0.145822333145509"
        rpy="0 0 0" />
      <mass
        value="0.27766" />
      <inertia
        ixx="3.15643646937588E-05"
        ixy="-1.52182890640833E-06"
        ixz="4.55164631847622E-07"
        iyy="3.67076280793159E-05"
        iyz="-1.96903029580603E-06"
        izz="1.43981727553149E-05" />
    </inertial>
    <visual>
      <origin
        xyz="0 0 0"
        rpy="0 0 0" />
      <geometry>
        <mesh
          filename="package://URDF_Forquad_V3/meshes/FL_Hip_yaw.STL" />
      </geometry>
      <material
        name="">
        <color
          rgba="0.792156862745098 0.819607843137255 0.933333333333333 1" />
      </material>
    </visual>
    <collision>
      <origin
        xyz="0 0 0"
        rpy="0 0 0" />
      <geometry>
        <mesh
          filename="package://URDF_Forquad_V3/meshes/FL_Hip_yaw.STL" />
      </geometry>
    </collision>
  </link>
  <joint
    name="FL_Hip_yaw"
    type="revolute">
    <origin
      xyz="0 0 0"
      rpy="0 0 0" />
    <parent
      link="FL_Hip_pitch" />
    <child
      link="FL_Hip_yaw" />
    <axis
      xyz="-1 0 0" />
    <limit
      lower="-1.57"
      upper="0.698"
      effort="0"
      velocity="0" />
  </joint>
  <link
    name="FL_Knee_pitch">
    <inertial>
      <origin
        xyz="0.0207384443608828 -0.0015079709376951 0.0611231119465607"
        rpy="0 0 0" />
      <mass
        value="0.19904" />
      <inertia
        ixx="6.3473765292077E-05"
        ixy="-8.10334849777901E-09"
        ixz="6.46012481697894E-07"
        iyy="6.18345040128202E-05"
        iyz="-1.3746804990091E-06"
        izz="5.53120360441999E-06" />
    </inertial>
    <visual>
      <origin
        xyz="0 0 0"
        rpy="0 0 0" />
      <geometry>
        <mesh
          filename="package://URDF_Forquad_V3/meshes/FL_Knee_pitch.STL" />
      </geometry>
      <material
        name="">
        <color
          rgba="0.792156862745098 0.819607843137255 0.933333333333333 1" />
      </material>
    </visual>
    <collision>
      <origin
        xyz="0 0 0"
        rpy="0 0 0" />
      <geometry>
        <mesh
          filename="package://URDF_Forquad_V3/meshes/FL_Knee_pitch.STL" />
      </geometry>
    </collision>
  </link>
  <joint
    name="FL_Knee_pitch"
    type="revolute">
    <origin
      xyz="-0.00057453 0.014718 0.2"
      rpy="0 0 -1.5708" />
    <parent
      link="FL_Hip_yaw" />
    <child
      link="FL_Knee_pitch" />
    <axis
      xyz="-1 0 0" />
    <limit
      lower="-0.79"
      upper="2.6"
      effort="0"
      velocity="0" />
  </joint>
  <link
    name="FL_Ankle_pitch">
    <inertial>
      <origin
        xyz="-0.00948959106910839 -0.0210171708246346 -0.00499999999038364"
        rpy="0 0 0" />
      <mass
        value="0.10293" />
      <inertia
        ixx="7.45965892483639E-06"
        ixy="2.96894351956324E-09"
        ixz="8.61367822831933E-15"
        iyy="2.11043183006312E-05"
        iyz="3.65938879788216E-15"
        izz="1.38459166739823E-05" />
    </inertial>
    <visual>
      <origin
        xyz="0 0 0"
        rpy="0 0 0" />
      <geometry>
        <mesh
          filename="package://URDF_Forquad_V3/meshes/FL_Ankle_pitch.STL" />
      </geometry>
      <material
        name="">
        <color
          rgba="0.792156862745098 0.819607843137255 0.933333333333333 1" />
      </material>
    </visual>
    <collision>
      <origin
        xyz="0 0 0"
        rpy="0 0 0" />
      <geometry>
        <mesh
          filename="package://URDF_Forquad_V3/meshes/FL_Ankle_pitch.STL" />
      </geometry>
    </collision>
  </link>
  <joint
    name="FL_Ankle_pitch"
    type="revolute">
    <origin
      xyz="0.0102 0 0.2"
      rpy="-1.5708 0 1.5708" />
    <parent
      link="FL_Knee_pitch" />
    <child
      link="FL_Ankle_pitch" />
    <axis
      xyz="0 0 1" />
    <limit
      lower="-1.4"
      upper="1.4"
      effort="0"
      velocity="0" />
  </joint>
  <link
    name="FR_Hip_pitch">
    <inertial>
      <origin
        xyz="0.0176283564302068 -0.0183468009423621 0.00397368862540913"
        rpy="0 0 0" />
      <mass
        value="0.04037" />
      <inertia
        ixx="5.05235273150255E-06"
        ixy="-1.42173579712793E-07"
        ixz="1.20746110793972E-06"
        iyy="5.1787749086451E-06"
        iyz="7.60834015198952E-07"
        izz="1.83489689436975E-06" />
    </inertial>
    <visual>
      <origin
        xyz="0 0 0"
        rpy="0 0 0" />
      <geometry>
        <mesh
          filename="package://URDF_Forquad_V3/meshes/FR_Hip_pitch.STL" />
      </geometry>
      <material
        name="">
        <color
          rgba="0.792156862745098 0.819607843137255 0.933333333333333 1" />
      </material>
    </visual>
    <collision>
      <origin
        xyz="0 0 0"
        rpy="0 0 0" />
      <geometry>
        <mesh
          filename="package://URDF_Forquad_V3/meshes/FR_Hip_pitch.STL" />
      </geometry>
    </collision>
  </link>
  <joint
    name="FR_Hip_pitch"
    type="revolute">
    <origin
      xyz="-0.1683 -0.04325 0.15"
      rpy="1.5099 0 0" />
    <parent
      link="base_link" />
    <child
      link="FR_Hip_pitch" />
    <axis
      xyz="1 0 0" />
    <limit
      lower="-3.14"
      upper="0.785"
      effort="0"
      velocity="0" />
  </joint>
  <link
    name="FR_Hip_yaw">
    <inertial>
      <origin
        xyz="0.00856805371345123 -0.145558761170643 -0.00426714719933045"
        rpy="0 0 0" />
      <mass
        value="0.27665" />
      <inertia
        ixx="3.6664457531308E-05"
        ixy="1.98440629834362E-06"
        ixz="-1.5312593989805E-06"
        iyy="1.44743897455777E-05"
        iyz="-1.51808528992025E-06"
        izz="3.1522316691717E-05" />
    </inertial>
    <visual>
      <origin
        xyz="0 0 0"
        rpy="0 0 0" />
      <geometry>
        <mesh
          filename="package://URDF_Forquad_V3/meshes/FR_Hip_yaw.STL" />
      </geometry>
      <material
        name="">
        <color
          rgba="0.792156862745098 0.819607843137255 0.933333333333333 1" />
      </material>
    </visual>
    <collision>
      <origin
        xyz="0 0 0"
        rpy="0 0 0" />
      <geometry>
        <mesh
          filename="package://URDF_Forquad_V3/meshes/FR_Hip_yaw.STL" />
      </geometry>
    </collision>
  </link>
  <joint
    name="FR_Hip_yaw"
    type="revolute">
    <origin
      xyz="0 0 0"
      rpy="0 0 0" />
    <parent
      link="FR_Hip_pitch" />
    <child
      link="FR_Hip_yaw" />
    <axis
      xyz="0 0.06085 -0.99815" />
    <limit
      lower="-0.698"
      upper="1.57"
      effort="0"
      velocity="0" />
  </joint>
  <link
    name="FR_Knee_pitch">
    <inertial>
      <origin
        xyz="0.0196494082659256 -0.00268461727393552 -0.0607744926892393"
        rpy="0 0 0" />
      <mass
        value="0.20005" />
      <inertia
        ixx="6.34780592535586E-05"
        ixy="-2.17303252056784E-08"
        ixz="-6.45710343863763E-07"
        iyy="6.18689753867713E-05"
        iyz="2.78784806722058E-07"
        izz="5.50139276076889E-06" />
    </inertial>
    <visual>
      <origin
        xyz="0 0 0"
        rpy="0 0 0" />
      <geometry>
        <mesh
          filename="package://URDF_Forquad_V3/meshes/FR_Knee_pitch.STL" />
      </geometry>
      <material
        name="">
        <color
          rgba="0.792156862745098 0.819607843137255 0.933333333333333 1" />
      </material>
    </visual>
    <collision>
      <origin
        xyz="0 0 0"
        rpy="0 0 0" />
      <geometry>
        <mesh
          filename="package://URDF_Forquad_V3/meshes/FR_Knee_pitch.STL" />
      </geometry>
    </collision>
  </link>
  <joint
    name="FR_Knee_pitch"
    type="revolute">
    <origin
      xyz="0.013425 -0.1996 -0.012651"
      rpy="1.5294 0 -3.1416" />
    <parent
      link="FR_Hip_yaw" />
    <child
      link="FR_Knee_pitch" />
    <axis
      xyz="-1 0 0" />
    <limit
      lower="-2.6"
      upper="0.79"
      effort="0"
      velocity="0" />
  </joint>
  <link
    name="FR_Ankle_pitch">
    <inertial>
      <origin
        xyz="9.59304857772736E-12 -0.0210171707253609 0.014489591067842"
        rpy="0 0 0" />
      <mass
        value="0.10293" />
      <inertia
        ixx="1.38459166739823E-05"
        ixy="3.65933254550268E-15"
        ixz="-8.61368401999384E-15"
        iyy="2.11043183006312E-05"
        iyz="-2.96894351956708E-09"
        izz="7.45965892483638E-06" />
    </inertial>
    <visual>
      <origin
        xyz="0 0 0"
        rpy="0 0 0" />
      <geometry>
        <mesh
          filename="package://URDF_Forquad_V3/meshes/FR_Ankle_pitch.STL" />
      </geometry>
      <material
        name="">
        <color
          rgba="0.792156862745098 0.819607843137255 0.933333333333333 1" />
      </material>
    </visual>
    <collision>
      <origin
        xyz="0 0 0"
        rpy="0 0 0" />
      <geometry>
        <mesh
          filename="package://URDF_Forquad_V3/meshes/FR_Ankle_pitch.STL" />
      </geometry>
    </collision>
  </link>
  <joint
    name="FR_Ankle_pitch"
    type="revolute">
    <origin
      xyz="0.014 0.001111 -0.20006"
      rpy="1.5514 0 0" />
    <parent
      link="FR_Knee_pitch" />
    <child
      link="FR_Ankle_pitch" />
    <axis
      xyz="1 0 0" />
    <limit
      lower="-1.4"
      upper="1.4"
      effort="0"
      velocity="0" />
  </joint>
  <link
    name="BL_Hip_pitch">
    <inertial>
      <origin
        xyz="0.0176283564301993 -0.0183468009406358 0.00397368863338098"
        rpy="0 0 0" />
      <mass
        value="0.04037" />
      <inertia
        ixx="5.05235273150255E-06"
        ixy="-1.42173579188181E-07"
        ixz="1.20746110800149E-06"
        iyy="5.17877490930623E-06"
        iyz="7.60834013746124E-07"
        izz="1.83489689370863E-06" />
    </inertial>
    <visual>
      <origin
        xyz="0 0 0"
        rpy="0 0 0" />
      <geometry>
        <mesh
          filename="package://URDF_Forquad_V3/meshes/BL_Hip_pitch.STL" />
      </geometry>
      <material
        name="">
        <color
          rgba="0.792156862745098 0.819607843137255 0.933333333333333 1" />
      </material>
    </visual>
    <collision>
      <origin
        xyz="0 0 0"
        rpy="0 0 0" />
      <geometry>
        <mesh
          filename="package://URDF_Forquad_V3/meshes/BL_Hip_pitch.STL" />
      </geometry>
    </collision>
  </link>
  <joint
    name="BL_Hip_pitch"
    type="revolute">
    <origin
      xyz="0.0899 -0.04325 -0.15"
      rpy="1.5099 0 -3.1416" />
    <parent
      link="base_link" />
    <child
      link="BL_Hip_pitch" />
    <axis
      xyz="1 0 0" />
    <limit
      lower="-3.14"
      upper="0.785"
      effort="0"
      velocity="0" />
  </joint>
  <link
    name="BL_Hip_yaw">
    <inertial>
      <origin
        xyz="0.0084492479524793 -0.145194018104819 -0.0134968769885935"
        rpy="0 0 0" />
      <mass
        value="0.27766" />
      <inertia
        ixx="3.66687558677515E-05"
        ixy="1.95881064429683E-06"
        ixz="-1.11352358388663E-06"
        iyy="1.45325419656831E-05"
        iyz="-1.97407789139012E-06"
        izz="3.14688665939953E-05" />
    </inertial>
    <visual>
      <origin
        xyz="0 0 0"
        rpy="0 0 0" />
      <geometry>
        <mesh
          filename="package://URDF_Forquad_V3/meshes/BL_Hip_yaw.STL" />
      </geometry>
      <material
        name="">
        <color
          rgba="0.792156862745098 0.819607843137255 0.933333333333333 1" />
      </material>
    </visual>
    <collision>
      <origin
        xyz="0 0 0"
        rpy="0 0 0" />
      <geometry>
        <mesh
          filename="package://URDF_Forquad_V3/meshes/BL_Hip_yaw.STL" />
      </geometry>
    </collision>
  </link>
  <joint
    name="BL_Hip_yaw"
    type="revolute">
    <origin
      xyz="0 0 0"
      rpy="0 0 0" />
    <parent
      link="BL_Hip_pitch" />
    <child
      link="BL_Hip_yaw" />
    <axis
      xyz="0 0.0608499120477827 -0.998146927162418" />
    <limit
      lower="-0.698"
      upper="1.57"
      effort="0"
      velocity="0" />
  </joint>
  <link
    name="BL_Knee_pitch">
    <inertial>
      <origin
        xyz="0.0195384443608857 0.000319424707765761 -0.0611408763245866"
        rpy="0 0 0" />
      <mass
        value="0.19904" />
      <inertia
        ixx="6.3473765292077E-05"
        ixy="-4.45695912181632E-09"
        ixz="-6.46047928781642E-07"
        iyy="6.17597865087644E-05"
        iyz="-2.46799632203214E-06"
        izz="5.60592110847586E-06" />
    </inertial>
    <visual>
      <origin
        xyz="0 0 0"
        rpy="0 0 0" />
      <geometry>
        <mesh
          filename="package://URDF_Forquad_V3/meshes/BL_Knee_pitch.STL" />
      </geometry>
      <material
        name="">
        <color
          rgba="0.792156862745098 0.819607843137255 0.933333333333333 1" />
      </material>
    </visual>
    <collision>
      <origin
        xyz="0 0 0"
        rpy="0 0 0" />
      <geometry>
        <mesh
          filename="package://URDF_Forquad_V3/meshes/BL_Knee_pitch.STL" />
      </geometry>
    </collision>
  </link>
  <joint
    name="BL_Knee_pitch"
    type="revolute">
    <origin
      xyz="0.0134254666676616 -0.199603983172914 -0.0126514195296113"
      rpy="1.52935047960293 0 3.14159265358978" />
    <parent
      link="BL_Hip_yaw" />
    <child
      link="BL_Knee_pitch" />
    <axis
      xyz="-1 0 0" />
    <limit
      lower="-0.785"
      upper="2.62"
      effort="0"
      velocity="0" />
  </joint>
  <link
    name="BL_Ankle_pitch">
    <inertial>
      <origin
        xyz="-9.61032642354809E-12 -0.0210171708282602 -0.00448959089401595"
        rpy="0 0 0" />
      <mass
        value="0.10293" />
      <inertia
        ixx="1.38459166739823E-05"
        ixy="-3.6592625689188E-15"
        ixz="-8.61368629386229E-15"
        iyy="2.11043183006312E-05"
        iyz="2.96894351956357E-09"
        izz="7.45965892483638E-06" />
    </inertial>
    <visual>
      <origin
        xyz="0 0 0"
        rpy="0 0 0" />
      <geometry>
        <mesh
          filename="package://URDF_Forquad_V3/meshes/BL_Ankle_pitch.STL" />
      </geometry>
      <material
        name="">
        <color
          rgba="0.792156862745098 0.819607843137255 0.933333333333333 1" />
      </material>
    </visual>
    <collision>
      <origin
        xyz="0 0 0"
        rpy="0 0 0" />
      <geometry>
        <mesh
          filename="package://URDF_Forquad_V3/meshes/BL_Ankle_pitch.STL" />
      </geometry>
    </collision>
  </link>
  <joint
    name="BL_Ankle_pitch"
    type="revolute">
    <origin
      xyz="0.0140000000000059 0.00111096419381682 -0.200059405573843"
      rpy="1.55135464761704 0 0" />
    <parent
      link="BL_Knee_pitch" />
    <child
      link="BL_Ankle_pitch" />
    <axis
      xyz="-1 0 0" />
    <limit
      lower="-1.396"
      upper="1.396"
      effort="0"
      velocity="0" />
  </joint>
  <link
    name="BR_Hip_pitch">
    <inertial>
      <origin
        xyz="0.00603741316457517 0.0192625721793665 0.0180424979675008"
        rpy="0 0 0" />
      <mass
        value="0.04037" />
      <inertia
        ixx="1.74339705032599E-06"
        ixy="1.22565299206099E-06"
        ixz="-5.24677747866904E-07"
        iyy="5.02166848316155E-06"
        iyz="4.32112332240516E-08"
        izz="5.30095897117866E-06" />
    </inertial>
    <visual>
      <origin
        xyz="0 0 0"
        rpy="0 0 0" />
      <geometry>
        <mesh
          filename="package://URDF_Forquad_V3/meshes/BR_Hip_pitch.STL" />
      </geometry>
      <material
        name="">
        <color
          rgba="0.792156862745098 0.819607843137255 0.933333333333333 1" />
      </material>
    </visual>
    <collision>
      <origin
        xyz="0 0 0"
        rpy="0 0 0" />
      <geometry>
        <mesh
          filename="package://URDF_Forquad_V3/meshes/BR_Hip_pitch.STL" />
      </geometry>
    </collision>
  </link>
  <joint
    name="BR_Hip_pitch"
    type="revolute">
    <origin
      xyz="-0.0899000000003333 -0.0432500000006142 -0.150000000000064"
      rpy="3.14159265358979 0 1.5707963267949" />
    <parent
      link="base_link" />
    <child
      link="BR_Hip_pitch" />
    <axis
      xyz="0 1 0" />
    <limit
      lower="-0.785"
      upper="3.14"
      effort="0"
      velocity="0" />
  </joint>
  <link
    name="BR_Hip_yaw">
    <inertial>
      <origin
        xyz="-0.00488888735071229 0.00892040055745999 0.145625050846799"
        rpy="0 0 0" />
      <mass
        value="0.27665" />
      <inertia
        ixx="3.15620100318881E-05"
        ixy="-1.10330956451503E-06"
        ixz="9.14558703457839E-07"
        iyy="3.67033288217012E-05"
        iyz="-1.9691596789446E-06"
        izz="1.4395824849886E-05" />
    </inertial>
    <visual>
      <origin
        xyz="0 0 0"
        rpy="0 0 0" />
      <geometry>
        <mesh
          filename="package://URDF_Forquad_V3/meshes/BR_Hip_yaw.STL" />
      </geometry>
      <material
        name="">
        <color
          rgba="0.792156862745098 0.819607843137255 0.933333333333333 1" />
      </material>
    </visual>
    <collision>
      <origin
        xyz="0 0 0"
        rpy="0 0 0" />
      <geometry>
        <mesh
          filename="package://URDF_Forquad_V3/meshes/BR_Hip_yaw.STL" />
      </geometry>
    </collision>
  </link>
  <joint
    name="BR_Hip_yaw"
    type="revolute">
    <origin
      xyz="0 0 0"
      rpy="0 0 0" />
    <parent
      link="BR_Hip_pitch" />
    <child
      link="BR_Hip_yaw" />
    <axis
      xyz="-1 0 0" />
    <limit
      lower="-1.57"
      upper="0.698"
      effort="0"
      velocity="0" />
  </joint>
  <link
    name="BR_Knee_pitch">
    <inertial>
      <origin
        xyz="0.0208494082659336 0.00150262605450553 0.0608151974940691"
        rpy="0 0 0" />
      <mass
        value="0.20005" />
      <inertia
        ixx="6.34780592535586E-05"
        ixy="9.17331572859614E-09"
        ixz="6.46010762669813E-07"
        iyy="6.18368349553459E-05"
        iyz="1.37417844006156E-06"
        izz="5.53353319219424E-06" />
    </inertial>
    <visual>
      <origin
        xyz="0 0 0"
        rpy="0 0 0" />
      <geometry>
        <mesh
          filename="package://URDF_Forquad_V3/meshes/BR_Knee_pitch.STL" />
      </geometry>
      <material
        name="">
        <color
          rgba="0.792156862745098 0.819607843137255 0.933333333333333 1" />
      </material>
    </visual>
    <collision>
      <origin
        xyz="0 0 0"
        rpy="0 0 0" />
      <geometry>
        <mesh
          filename="package://URDF_Forquad_V3/meshes/BR_Knee_pitch.STL" />
      </geometry>
    </collision>
  </link>
  <joint
    name="BR_Knee_pitch"
    type="revolute">
    <origin
      xyz="-0.000574533332338027 0.0147179092927324 0.20000394021908"
      rpy="0 0 -1.5707963267949" />
    <parent
      link="BR_Hip_yaw" />
    <child
      link="BR_Knee_pitch" />
    <axis
      xyz="-1 0 0" />
    <limit
      lower="-2.62"
      upper="0.785"
      effort="0"
      velocity="0" />
  </joint>
  <link
    name="BR_Ankle_pitch">
    <inertial>
      <origin
        xyz="0.00948959089401438 0.0210171707289529 0.00500000000960039"
        rpy="0 0 0" />
      <mass
        value="0.10293" />
      <inertia
        ixx="7.45965892483638E-06"
        ixy="2.96894351956874E-09"
        ixz="-8.6136753112845E-15"
        iyy="2.11043183006312E-05"
        iyz="-3.65935998011421E-15"
        izz="1.38459166739823E-05" />
    </inertial>
    <visual>
      <origin
        xyz="0 0 0"
        rpy="0 0 0" />
      <geometry>
        <mesh
          filename="package://URDF_Forquad_V3/meshes/BR_Ankle_pitch.STL" />
      </geometry>
      <material
        name="">
        <color
          rgba="0.792156862745098 0.819607843137255 0.933333333333333 1" />
      </material>
    </visual>
    <collision>
      <origin
        xyz="0 0 0"
        rpy="0 0 0" />
      <geometry>
        <mesh
          filename="package://URDF_Forquad_V3/meshes/BR_Ankle_pitch.STL" />
      </geometry>
    </collision>
  </link>
  <joint
    name="BR_Ankle_pitch"
    type="revolute">
    <origin
      xyz="0.0102000000000013 0 0.2"
      rpy="1.57079632679489 0 1.5707963267949" />
    <parent
      link="BR_Knee_pitch" />
    <child
      link="BR_Ankle_pitch" />
    <axis
      xyz="0 0 -1" />
    <limit
      lower="-1.396"
      upper="1.396"
      effort="0"
      velocity="0" />
  </joint>
</robot>