<?xml version="1.0" encoding="utf-8"?>
<!-- This URDF was automatically created by SolidWorks to URDF Exporter! Originally created by Stephen Brawner (brawner@gmail.com) 
     Commit Version: 1.6.0-4-g7f85cfe  Build Version: 1.6.7995.38578
     For more information, please see http://wiki.ros.org/sw_urdf_exporter -->
<robot
  name="V3">
  <link
    name="base_link">
    <inertial>
      <origin
        xyz="0.00050091090873388 -0.00998629103930559 0.0173218447986229"
        rpy="0 0 0" />
      <mass
        value="0.33504" />
      <inertia
        ixx="1.97764712583923E-05"
        ixy="2.95428059624505E-09"
        ixz="-2.25102941158599E-08"
        iyy="7.26645068369103E-05"
        iyz="-1.73059202753526E-06"
        izz="6.99381839815544E-05" />
    </inertial>
    <visual>
      <origin
        xyz="0 0 0"
        rpy="0 0 0" />
      <geometry>
        <mesh
          filename="package://V3/meshes/base_link.STL" />
      </geometry>
      <material
        name="">
        <color
          rgba="0.792156862745098 0.819607843137255 0.933333333333333 1" />
      </material>
    </visual>
    <collision>
      <origin
        xyz="0 0 0"
        rpy="0 0 0" />
      <geometry>
        <mesh
          filename="package://V3/meshes/base_link.STL" />
      </geometry>
    </collision>
  </link>
  <link
    name="Waist">
    <inertial>
      <origin
        xyz="-8.30608247112674E-11 0.0324696863156453 0.00531795471648416"
        rpy="0 0 0" />
      <mass
        value="0.0152478549678287" />
      <inertia
        ixx="9.63125992413617E-06"
        ixy="-4.11230545538282E-14"
        ixz="-1.78226542265837E-14"
        iyy="5.88153288004389E-06"
        iyz="1.47868590781889E-07"
        izz="5.40129346132741E-06" />
    </inertial>
    <visual>
      <origin
        xyz="0 0 0"
        rpy="0 0 0" />
      <geometry>
        <mesh
          filename="package://V3/meshes/Waist.STL" />
      </geometry>
      <material
        name="">
        <color
          rgba="1 1 1 1" />
      </material>
    </visual>
    <collision>
      <origin
        xyz="0 0 0"
        rpy="0 0 0" />
      <geometry>
        <mesh
          filename="package://V3/meshes/Waist.STL" />
      </geometry>
    </collision>
  </link>
  <joint
    name="Waist"
    type="revolute">
    <origin
      xyz="0.00275 0 0.042110000000001"
      rpy="1.5707963267949 0 0" />
    <parent
      link="base_link" />
    <child
      link="Waist" />
    <axis
      xyz="0 0 1" />
    <limit
      lower="-0.52"
      upper="0.52"
      effort="0"
      velocity="0" />
  </joint>
  <link
    name="Waist_2">
    <inertial>
      <origin
        xyz="0.00048892162819197 0.158904911204199 -0.00145233666018986"
        rpy="0 0 0" />
      <mass
        value="0.66174" />
      <inertia
        ixx="0.000601071923731556"
        ixy="1.28924517290492E-06"
        ixz="2.54284162583461E-05"
        iyy="0.000814982910525989"
        iyz="1.10939073171587E-05"
        izz="0.00113760922496659" />
    </inertial>
    <visual>
      <origin
        xyz="0 0 0"
        rpy="0 0 0" />
      <geometry>
        <mesh
          filename="package://V3/meshes/Waist_2.STL" />
      </geometry>
      <material
        name="">
        <color
          rgba="0.792156862745098 0.819607843137255 0.933333333333333 1" />
      </material>
    </visual>
    <collision>
      <origin
        xyz="0 0 0"
        rpy="0 0 0" />
      <geometry>
        <mesh
          filename="package://V3/meshes/Waist_2.STL" />
      </geometry>
    </collision>
  </link>
  <joint
    name="Waist_2"
    type="revolute">
    <origin
      xyz="0 0.0216051320794004 0.000669999999999147"
      rpy="-3.14159265358979 0 3.13862236818707" />
    <parent
      link="Waist" />
    <child
      link="Waist_2" />
    <axis
      xyz="-0.00297028103512349 -0.999995588705556 0" />
    <limit
      lower="-3.14"
      upper="3.14"
      effort="0"
      velocity="0" />
  </joint>
  <link
    name="RSDp">
    <inertial>
      <origin
        xyz="0.029365339777939 -0.0145376874428952 -0.0120536310806074"
        rpy="0 0 0" />
      <mass
        value="0.02666" />
      <inertia
        ixx="2.4185481628886E-06"
        ixy="4.81669677091078E-08"
        ixz="3.69839487042427E-07"
        iyy="2.62122104926124E-06"
        iyz="-1.15971922654066E-07"
        izz="8.26141091388542E-07" />
    </inertial>
    <visual>
      <origin
        xyz="0 0 0"
        rpy="0 0 0" />
      <geometry>
        <mesh
          filename="package://V3/meshes/RSDp.STL" />
      </geometry>
      <material
        name="">
        <color
          rgba="0.792156862745098 0.819607843137255 0.933333333333333 1" />
      </material>
    </visual>
    <collision>
      <origin
        xyz="0 0 0"
        rpy="0 0 0" />
      <geometry>
        <mesh
          filename="package://V3/meshes/RSDp.STL" />
      </geometry>
    </collision>
  </link>
  <joint
    name="RSDp"
    type="revolute">
    <origin
      xyz="-0.0810547566654313 0.133916214070981 0.00336599597935944"
      rpy="3.06976714570975 -0.053568299660757 3.13862236818707" />
    <parent
      link="Waist_2" />
    <child
      link="RSDp" />
    <axis
      xyz="1 0 0" />
    <limit
      lower="-0.75"
      upper="1.57"
      effort="0"
      velocity="0" />
  </joint>
  <link
    name="RSDy">
    <inertial>
      <origin
        xyz="-0.00268951566935519 -0.0432907123235494 -0.0121725877314745"
        rpy="0 0 0" />
      <mass
        value="0.00796" />
      <inertia
        ixx="7.44326056980046E-07"
        ixy="9.46622369551179E-08"
        ixz="4.1290536417383E-08"
        iyy="5.11482673925875E-07"
        iyz="2.03709556090735E-07"
        izz="4.13356846017119E-07" />
    </inertial>
    <visual>
      <origin
        xyz="0 0 0"
        rpy="0 0 0" />
      <geometry>
        <mesh
          filename="package://V3/meshes/RSDy.STL" />
      </geometry>
      <material
        name="">
        <color
          rgba="0.792156862745098 0.819607843137255 0.933333333333333 1" />
      </material>
    </visual>
    <collision>
      <origin
        xyz="0 0 0"
        rpy="0 0 0" />
      <geometry>
        <mesh
          filename="package://V3/meshes/RSDy.STL" />
      </geometry>
    </collision>
  </link>
  <joint
    name="RSDy"
    type="revolute">
    <origin
      xyz="0.047234445750881 0.0100000000000018 -0.00610999999999955"
      rpy="0 0 0" />
    <parent
      link="RSDp" />
    <child
      link="RSDy" />
    <axis
      xyz="0 0.0717637669963114 -0.9974216569468" />
    <limit
      lower="-1.39"
      upper="0.14"
      effort="0"
      velocity="0" />
  </joint>
  <link
    name="RSDr">
    <inertial>
      <origin
        xyz="-0.000648993351435506 -0.0644490658095404 -0.00501037463776728"
        rpy="0 0 0" />
      <mass
        value="0.21670" />
      <inertia
        ixx="5.2705855755284E-06"
        ixy="4.82411697262524E-09"
        ixz="-1.90476291295014E-07"
        iyy="3.88872299888649E-06"
        iyz="1.83876643864369E-07"
        izz="5.30321918043652E-06" />
    </inertial>
    <visual>
      <origin
        xyz="0 0 0"
        rpy="0 0 0" />
      <geometry>
        <mesh
          filename="package://V3/meshes/RSDr.STL" />
      </geometry>
      <material
        name="">
        <color
          rgba="0.792156862745098 0.819607843137255 0.933333333333333 1" />
      </material>
    </visual>
    <collision>
      <origin
        xyz="0 0 0"
        rpy="0 0 0" />
      <geometry>
        <mesh
          filename="package://V3/meshes/RSDr.STL" />
      </geometry>
    </collision>
  </link>
  <joint
    name="RSDr"
    type="revolute">
    <origin
      xyz="-0.00521918016205247 -0.0572706907633618 0.00268037895526259"
      rpy="3.06346884034212 0.00280395002747017 -3.10593935078835" />
    <parent
      link="RSDy" />
    <child
      link="RSDr" />
    <axis
      xyz="0.035754924801615 -0.999340423672474 -0.00634846174690388" />
    <limit
      lower="-0.22"
      upper="1.47"
      effort="0"
      velocity="0" />
  </joint>
  <link
    name="RARMp">
    <inertial>
      <origin
        xyz="-0.0109855620136424 -0.0393014331349118 -0.00773020942152066"
        rpy="0 0 0" />
      <mass
        value="0.13866" />
      <inertia
        ixx="5.8944608141404E-06"
        ixy="4.34439663989622E-08"
        ixz="4.87026070269323E-08"
        iyy="1.84730677144131E-06"
        iyz="-1.05630143241146E-08"
        izz="4.82704520175826E-06" />
    </inertial>
    <visual>
      <origin
        xyz="0 0 0"
        rpy="0 0 0" />
      <geometry>
        <mesh
          filename="package://V3/meshes/RARMp.STL" />
      </geometry>
      <material
        name="">
        <color
          rgba="0.792156862745098 0.819607843137255 0.933333333333333 1" />
      </material>
    </visual>
    <collision>
      <origin
        xyz="0 0 0"
        rpy="0 0 0" />
      <geometry>
        <mesh
          filename="package://V3/meshes/RARMp.STL" />
      </geometry>
    </collision>
  </link>
  <joint
    name="RARMp"
    type="revolute">
    <origin
      xyz="0.0033115 -0.092555 -0.00059797"
      rpy="0.0063485 1.1667E-05 0.035763" />
    <parent
      link="RSDr" />
    <child
      link="RARMp" />
    <axis
      xyz="1 0 0" />
    <limit
      lower="-1.57"
      upper="0.29"
      effort="0"
      velocity="0" />
  </joint>
  <link
    name="RARMAP">
    <inertial>
      <origin
        xyz="-1.68452360393978E-09 1.78252146376678E-09 1.87540552878951E-09"
        rpy="0 0 0" />
      <mass
        value="0.00289" />
      <inertia
        ixx="3.47835662925469E-08"
        ixy="-8.69331885005767E-21"
        ixz="-9.15043785998522E-21"
        iyy="3.47835662925478E-08"
        iyz="9.64835680100363E-21"
        izz="3.47835662925488E-08" />
    </inertial>
    <visual>
      <origin
        xyz="0 0 0"
        rpy="0 0 0" />
      <geometry>
        <mesh
          filename="package://V3/meshes/RARMAP.STL" />
      </geometry>
      <material
        name="">
        <color
          rgba="0.776470588235294 0.756862745098039 0.737254901960784 1" />
      </material>
    </visual>
    <collision>
      <origin
        xyz="0 0 0"
        rpy="0 0 0" />
      <geometry>
        <mesh
          filename="package://V3/meshes/RARMAP.STL" />
      </geometry>
    </collision>
  </link>
  <joint
    name="RARMAP"
    type="revolute">
    <origin
      xyz="-0.00350000000000036 -0.140000000000001 0"
      rpy="-3.14159265358978 0.0535682996607567 3.14159265358979" />
    <parent
      link="RARMp" />
    <child
      link="RARMAP" />
    <axis
      xyz="-0.998565561702505 0 0.0535426837370016" />
    <limit
      lower="-0.06"
      upper="0.43"
      effort="0"
      velocity="0" />
  </joint>
  <link
    name="RARMAy">
    <inertial>
      <origin
        xyz="-2.19445628335535E-10 -0.0174193425200825 0.0244034803681567"
        rpy="0 0 0" />
      <mass
        value="0.02488" />
      <inertia
        ixx="5.08058079936302E-06"
        ixy="1.68282660446282E-14"
        ixz="8.1798155085746E-15"
        iyy="6.07928688954362E-06"
        iyz="2.7604838016127E-09"
        izz="1.17720006677435E-06" />
    </inertial>
    <visual>
      <origin
        xyz="0 0 0"
        rpy="0 0 0" />
      <geometry>
        <mesh
          filename="package://V3/meshes/RARMAy.STL" />
      </geometry>
      <material
        name="">
        <color
          rgba="0.792156862745098 0.819607843137255 0.933333333333333 1" />
      </material>
    </visual>
    <collision>
      <origin
        xyz="0 0 0"
        rpy="0 0 0" />
      <geometry>
        <mesh
          filename="package://V3/meshes/RARMAy.STL" />
      </geometry>
    </collision>
  </link>
  <joint
    name="RARMAy"
    type="revolute">
    <origin
      xyz="0 0 0"
      rpy="0 0.0535682996607567 0" />
    <parent
      link="RARMAP" />
    <child
      link="RARMAy" />
    <axis
      xyz="0 0 1" />
    <limit
      lower="-0.17"
      upper="0.17"
      effort="0"
      velocity="0" />
  </joint>
  <link
    name="LSDp">
    <inertial>
      <origin
        xyz="-0.0264850638874404 -0.0161380599865885 -0.0115557024217441"
        rpy="0 0 0" />
      <mass
        value="0.02666" />
      <inertia
        ixx="2.40080281350151E-06"
        ixy="-7.45183864648936E-08"
        ixz="-3.65127810019035E-07"
        iyy="2.58667384237348E-06"
        iyz="-2.43286627561113E-07"
        izz="8.42040299247692E-07" />
    </inertial>
    <visual>
      <origin
        xyz="0 0 0"
        rpy="0 0 0" />
      <geometry>
        <mesh
          filename="package://V3/meshes/LSDp.STL" />
      </geometry>
      <material
        name="">
        <color
          rgba="0.792156862745098 0.819607843137255 0.933333333333333 1" />
      </material>
    </visual>
    <collision>
      <origin
        xyz="0 0 0"
        rpy="0 0 0" />
      <geometry>
        <mesh
          filename="package://V3/meshes/LSDp.STL" />
      </geometry>
    </collision>
  </link>
  <joint
    name="LSDp"
    type="revolute">
    <origin
      xyz="0.0859748782366248 0.133420086925566 -0.00559010536299459"
      rpy="3.14146501023636 -0.0525111635115858 3.14100632419705" />
    <parent
      link="Waist_2" />
    <child
      link="LSDp" />
    <axis
      xyz="0.999996607597238 0.0023806690533142 -0.00105698101866506" />
    <limit
      lower="-0.75"
      upper="1.57"
      effort="0"
      velocity="0" />
  </joint>
  <link
    name="LSDy">
    <inertial>
      <origin
        xyz="-0.00853936372152249 -0.0344797499848761 -0.0158346788164377"
        rpy="0 0 0" />
      <mass
        value="0.00796" />
      <inertia
        ixx="7.44326056980032E-07"
        ixy="-9.73813296686781E-08"
        ixz="-3.4390756533452E-08"
        iyy="5.40139866980604E-07"
        iyz="1.9458760940736E-07"
        izz="3.8469965296239E-07" />
    </inertial>
    <visual>
      <origin
        xyz="0 0 0"
        rpy="0 0 0" />
      <geometry>
        <mesh
          filename="package://V3/meshes/LSDy.STL" />
      </geometry>
      <material
        name="">
        <color
          rgba="0.792156862745098 0.819607843137255 0.933333333333333 1" />
      </material>
    </visual>
    <collision>
      <origin
        xyz="0 0 0"
        rpy="0 0 0" />
      <geometry>
        <mesh
          filename="package://V3/meshes/LSDy.STL" />
      </geometry>
    </collision>
  </link>
  <joint
    name="LSDy"
    type="revolute">
    <origin
      xyz="-0.0318066577317343 5.65176842755588E-05 -6.63980795845814E-05"
      rpy="0 0 0" />
    <parent
      link="LSDp" />
    <child
      link="LSDy" />
    <axis
      xyz="-0.00105698401394164 0 -0.999999441392241" />
    <limit
      lower="-0.14"
      upper="1.39"
      effort="0"
      velocity="0" />
  </joint>
  <link
    name="LSDr">
    <inertial>
      <origin
        xyz="-0.000141821718329591 -0.0647171132525845 -0.00916727769024185"
        rpy="0 0 0" />
      <mass
        value="0.21670" />
      <inertia
        ixx="5.32090282853741E-06"
        ixy="-4.50566976959882E-08"
        ixz="1.80744272504802E-07"
        iyy="3.89871010021898E-06"
        iyz="9.66718121994144E-08"
        izz="5.34945047353967E-06" />
    </inertial>
    <visual>
      <origin
        xyz="0 0 0"
        rpy="0 0 0" />
      <geometry>
        <mesh
          filename="package://V3/meshes/LSDr.STL" />
      </geometry>
      <material
        name="">
        <color
          rgba="0.792156862745098 0.819607843137255 0.933333333333333 1" />
      </material>
    </visual>
    <collision>
      <origin
        xyz="0 0 0"
        rpy="0 0 0" />
      <geometry>
        <mesh
          filename="package://V3/meshes/LSDr.STL" />
      </geometry>
    </collision>
  </link>
  <joint
    name="LSDr"
    type="revolute">
    <origin
      xyz="-0.00599999999999998 -0.0471154508071299 0"
      rpy="3.06976714570974 -0.00105698421072618 3.14159265358979" />
    <parent
      link="LSDy" />
    <child
      link="LSDr" />
    <axis
      xyz="0 -0.9974216569468 -0.0717637669963115" />
    <limit
      lower="-1.47"
      upper="0.22"
      effort="0"
      velocity="0" />
  </joint>
  <link
    name="LARMp">
    <inertial>
      <origin
        xyz="0.00720772208529306 -0.0378379502783512 -0.00744235818635385"
        rpy="0 0 0" />
      <mass
        value="0.13866" />
      <inertia
        ixx="5.94426076058107E-06"
        ixy="-4.3741422932966E-08"
        ixz="-5.50325462488362E-08"
        iyy="1.87318690292225E-06"
        iyz="-1.04237146319795E-08"
        izz="4.85241707012103E-06" />
    </inertial>
    <visual>
      <origin
        xyz="0 0 0"
        rpy="0 0 0" />
      <geometry>
        <mesh
          filename="package://V3/meshes/LARMp.STL" />
      </geometry>
      <material
        name="">
        <color
          rgba="0.792156862745098 0.819607843137255 0.933333333333333 1" />
      </material>
    </visual>
    <collision>
      <origin
        xyz="0 0 0"
        rpy="0 0 0" />
      <geometry>
        <mesh
          filename="package://V3/meshes/LARMp.STL" />
      </geometry>
    </collision>
  </link>
  <joint
    name="LARMp"
    type="revolute">
    <origin
      xyz="0 -0.092565681816204 -0.00666003387379006"
      rpy="0.0718255078798755 0 0" />
    <parent
      link="LSDr" />
    <child
      link="LARMp" />
    <axis
      xyz="-1 0 0" />
    <limit
      lower="-0.29"
      upper="1.57"
      effort="0"
      velocity="0" />
  </joint>
  <link
    name="LARMAp">
    <inertial>
      <origin
        xyz="1.782521449889E-09 1.78252097110532E-09 -1.78252150540015E-09"
        rpy="0 0 0" />
      <mass
        value="0.00289" />
      <inertia
        ixx="3.47835662925479E-08"
        ixy="9.18843897040946E-21"
        ixz="-9.18640123540619E-21"
        iyy="3.47835662925479E-08"
        iyz="-9.18749506362648E-21"
        izz="3.47835662925479E-08" />
    </inertial>
    <visual>
      <origin
        xyz="0 0 0"
        rpy="0 0 0" />
      <geometry>
        <mesh
          filename="package://V3/meshes/LARMAp.STL" />
      </geometry>
      <material
        name="">
        <color
          rgba="0.776470588235294 0.756862745098039 0.737254901960784 1" />
      </material>
    </visual>
    <collision>
      <origin
        xyz="0 0 0"
        rpy="0 0 0" />
      <geometry>
        <mesh
          filename="package://V3/meshes/LARMAp.STL" />
      </geometry>
    </collision>
  </link>
  <joint
    name="LARMAp"
    type="revolute">
    <origin
      xyz="0 -0.14 0"
      rpy="1.5707963267949 0 -1.57079632679495" />
    <parent
      link="LARMp" />
    <child
      link="LARMAp" />
    <axis
      xyz="0 0 -1" />
    <limit
      lower="-0.06"
      upper="0.43"
      effort="0"
      velocity="0" />
  </joint>
  <link
    name="LARMAy">
    <inertial>
      <origin
        xyz="2.13694381634433E-10 -0.0174193425571761 -0.024403480485095"
        rpy="0 0 0" />
      <mass
        value="0.02488" />
      <inertia
        ixx="5.08058079734746E-06"
        ixy="-1.65419041207627E-14"
        ixz="8.13063643154988E-15"
        iyy="6.07928688955585E-06"
        iyz="-2.76048381992039E-09"
        izz="1.17720006436185E-06" />
    </inertial>
    <visual>
      <origin
        xyz="0 0 0"
        rpy="0 0 0" />
      <geometry>
        <mesh
          filename="package://V3/meshes/LARMAy.STL" />
      </geometry>
      <material
        name="">
        <color
          rgba="0.792156862745098 0.819607843137255 0.933333333333333 1" />
      </material>
    </visual>
    <collision>
      <origin
        xyz="0 0 0"
        rpy="0 0 0" />
      <geometry>
        <mesh
          filename="package://V3/meshes/LARMAy.STL" />
      </geometry>
    </collision>
  </link>
  <joint
    name="LARMAy"
    type="revolute">
    <origin
      xyz="0 0 0"
      rpy="-1.5707963267949 1.57079631189374 0" />
    <parent
      link="LARMAp" />
    <child
      link="LARMAy" />
    <axis
      xyz="0 0 1" />
    <limit
      lower="-0.17"
      upper="0.17"
      effort="0"
      velocity="0" />
  </joint>
  <link
    name="RHIPp">
    <inertial>
      <origin
        xyz="0.0295665493479005 -0.0145376874433172 -0.0120536310802667"
        rpy="0 0 0" />
      <mass
        value="0.02666" />
      <inertia
        ixx="2.41854816289442E-06"
        ixy="4.81669677340809E-08"
        ixz="3.69839487107744E-07"
        iyy="2.62122104924701E-06"
        iyz="-1.1597192265796E-07"
        izz="8.26141091389484E-07" />
    </inertial>
    <visual>
      <origin
        xyz="0 0 0"
        rpy="0 0 0" />
      <geometry>
        <mesh
          filename="package://V3/meshes/RHIPp.STL" />
      </geometry>
      <material
        name="">
        <color
          rgba="0.792156862745098 0.819607843137255 0.933333333333333 1" />
      </material>
    </visual>
    <collision>
      <origin
        xyz="0 0 0"
        rpy="0 0 0" />
      <geometry>
        <mesh
          filename="package://V3/meshes/RHIPp.STL" />
      </geometry>
    </collision>
  </link>
  <joint
    name="RHIPp"
    type="revolute">
    <origin
      xyz="0.0177143446801997 0 0"
      rpy="1.49897081891485 0 0" />
    <parent
      link="base_link" />
    <child
      link="RHIPp" />
    <axis
      xyz="-1 0 0" />
    <limit
      lower="-1.57"
      upper="0.75"
      effort="0"
      velocity="0" />
  </joint>
  <link
    name="RHIPy">
    <inertial>
      <origin
        xyz="-0.00268951566935543 -0.0432907123235494 -0.0121725877314746"
        rpy="0 0 0" />
      <mass
        value="0.00796" />
      <inertia
        ixx="7.44326056980044E-07"
        ixy="9.46622369551162E-08"
        ixz="4.12905364173838E-08"
        iyy="5.11482673925872E-07"
        iyz="2.03709556090734E-07"
        izz="4.13356846017117E-07" />
    </inertial>
    <visual>
      <origin
        xyz="0 0 0"
        rpy="0 0 0" />
      <geometry>
        <mesh
          filename="package://V3/meshes/RHIPy.STL" />
      </geometry>
      <material
        name="">
        <color
          rgba="0.792156862745098 0.819607843137255 0.933333333333333 1" />
      </material>
    </visual>
    <collision>
      <origin
        xyz="0 0 0"
        rpy="0 0 0" />
      <geometry>
        <mesh
          filename="package://V3/meshes/RHIPy.STL" />
      </geometry>
    </collision>
  </link>
  <joint
    name="RHIPy"
    type="revolute">
    <origin
      xyz="0.0474356553198006 0.0100000000000004 -0.00610999999999983"
      rpy="0 0 0" />
    <parent
      link="RHIPp" />
    <child
      link="RHIPy" />
    <axis
      xyz="0 0.071763766996305 -0.9974216569468" />
    <limit
      lower="-1.39"
      upper="0.14"
      effort="0"
      velocity="0" />
  </joint>
  <link
    name="RHIPr">
    <inertial>
      <origin
        xyz="-0.000141821553682274 -0.0645546760091016 -0.00915559046551466"
        rpy="0 0 0" />
      <mass
        value="0.21670" />
      <inertia
        ixx="5.32090280918624E-06"
        ixy="-4.50567007702021E-08"
        ixz="1.80744274836868E-07"
        iyy="3.89871007897009E-06"
        iyz="9.6671813958189E-08"
        izz="5.34945045361263E-06" />
    </inertial>
    <visual>
      <origin
        xyz="0 0 0"
        rpy="0 0 0" />
      <geometry>
        <mesh
          filename="package://V3/meshes/RHIPr.STL" />
      </geometry>
      <material
        name="">
        <color
          rgba="0.792156862745098 0.819607843137255 0.933333333333333 1" />
      </material>
    </visual>
    <collision>
      <origin
        xyz="0 0 0"
        rpy="0 0 0" />
      <geometry>
        <mesh
          filename="package://V3/meshes/RHIPr.STL" />
      </geometry>
    </collision>
  </link>
  <joint
    name="RHIPr"
    type="revolute">
    <origin
      xyz="-0.00521918016205408 -0.0572444722453131 0.00268226535867852"
      rpy="0 0 0" />
    <parent
      link="RHIPy" />
    <child
      link="RHIPr" />
    <axis
      xyz="0 0.9974216569468 0.0717637669963113" />
    <limit
      lower="-0.22"
      upper="1.47"
      effort="0"
      velocity="0" />
  </joint>
  <link
    name="RKNEEP">
    <inertial>
      <origin
        xyz="0.0072077220770915 -0.0378379504038629 -0.00744235817106062"
        rpy="0 0 0" />
      <mass
        value="0.13866" />
      <inertia
        ixx="5.94426076092898E-06"
        ixy="-4.37414228336997E-08"
        ixz="-5.50325465299912E-08"
        iyy="1.87318690309453E-06"
        iyz="-1.04237148446069E-08"
        izz="4.85241707227756E-06" />
    </inertial>
    <visual>
      <origin
        xyz="0 0 0"
        rpy="0 0 0" />
      <geometry>
        <mesh
          filename="package://V3/meshes/RKNEEP.STL" />
      </geometry>
      <material
        name="">
        <color
          rgba="0.792156862745098 0.819607843137255 0.933333333333333 1" />
      </material>
    </visual>
    <collision>
      <origin
        xyz="0 0 0"
        rpy="0 0 0" />
      <geometry>
        <mesh
          filename="package://V3/meshes/RKNEEP.STL" />
      </geometry>
    </collision>
  </link>
  <joint
    name="RKNEEP"
    type="revolute">
    <origin
      xyz="0 -0.0924032447345287 -0.00664834664321953"
      rpy="0.0697545658569862 0 0" />
    <parent
      link="RHIPr" />
    <child
      link="RKNEEP" />
    <axis
      xyz="-1 0 0" />
    <limit
      lower="-0.29"
      upper="1.57"
      effort="0"
      velocity="0" />
  </joint>
  <link
    name="RANKLEp">
    <inertial>
      <origin
        xyz="-1.78252151927794E-09 -1.78252151927794E-09 1.78252145872524E-09"
        rpy="0 0 0" />
      <mass
        value="0.00289" />
      <inertia
        ixx="3.47835662925478E-08"
        ixy="9.24139804093278E-21"
        ixz="-9.20420174126396E-21"
        iyy="3.47835662925479E-08"
        iyz="-9.16812094271684E-21"
        izz="3.47835662925479E-08" />
    </inertial>
    <visual>
      <origin
        xyz="0 0 0"
        rpy="0 0 0" />
      <geometry>
        <mesh
          filename="package://V3/meshes/RANKLEp.STL" />
      </geometry>
      <material
        name="">
        <color
          rgba="0.776470588235294 0.756862745098039 0.737254901960784 1" />
      </material>
    </visual>
    <collision>
      <origin
        xyz="0 0 0"
        rpy="0 0 0" />
      <geometry>
        <mesh
          filename="package://V3/meshes/RANKLEp.STL" />
      </geometry>
    </collision>
  </link>
  <joint
    name="RANKLEp"
    type="revolute">
    <origin
      xyz="0 -0.14 0"
      rpy="0 0 0" />
    <parent
      link="RKNEEP" />
    <child
      link="RANKLEp" />
    <axis
      xyz="-1 0 0" />
    <limit
      lower="-0.43"
      upper="0.06"
      effort="0"
      velocity="0" />
  </joint>
  <link
    name="RANKLEy">
    <inertial>
      <origin
        xyz="5.10645789542075E-09 -0.01741934255127 -0.0244034804778275"
        rpy="0 0 0" />
      <mass
        value="0.02488" />
      <inertia
        ixx="5.08058079768079E-06"
        ixy="-1.58607064344923E-14"
        ixz="7.904625915327E-13"
        iyy="6.07928688952841E-06"
        iyz="-2.76048316670902E-09"
        izz="1.17720006487251E-06" />
    </inertial>
    <visual>
      <origin
        xyz="0 0 0"
        rpy="0 0 0" />
      <geometry>
        <mesh
          filename="package://V3/meshes/RANKLEy.STL" />
      </geometry>
      <material
        name="">
        <color
          rgba="0.792156862745098 0.819607843137255 0.933333333333333 1" />
      </material>
    </visual>
    <collision>
      <origin
        xyz="0 0 0"
        rpy="0 0 0" />
      <geometry>
        <mesh
          filename="package://V3/meshes/RANKLEy.STL" />
      </geometry>
    </collision>
  </link>
  <joint
    name="RANKLEy"
    type="revolute">
    <origin
      xyz="0 0 0"
      rpy="0 0 -9.67762128952663E-05" />
    <parent
      link="RANKLEp" />
    <child
      link="RANKLEy" />
    <axis
      xyz="0 0 0.99999999999998" />
    <limit
      lower="-0.17"
      upper="0.17"
      effort="0"
      velocity="0" />
  </joint>
  <link
    name="LHIPp">
    <inertial>
      <origin
        xyz="-0.0267534699752652 -0.0161386989748455 -0.0115554187206658"
        rpy="0 0 0" />
      <mass
        value="0.02666" />
      <inertia
        ixx="2.40080281351025E-06"
        ixy="-7.45183864662649E-08"
        ixz="-3.65127810022732E-07"
        iyy="2.58667384237902E-06"
        iyz="-2.43286627563919E-07"
        izz="8.4204029924739E-07" />
    </inertial>
    <visual>
      <origin
        xyz="0 0 0"
        rpy="0 0 0" />
      <geometry>
        <mesh
          filename="package://V3/meshes/LHIPp.STL" />
      </geometry>
      <material
        name="">
        <color
          rgba="0.792156862745098 0.819607843137255 0.933333333333333 1" />
      </material>
    </visual>
    <collision>
      <origin
        xyz="0 0 0"
        rpy="0 0 0" />
      <geometry>
        <mesh
          filename="package://V3/meshes/LHIPp.STL" />
      </geometry>
    </collision>
  </link>
  <joint
    name="LHIPp"
    type="revolute">
    <origin
      xyz="-0.0223720047342062 0 0"
      rpy="1.57079381045863 0.00238066997222939 -0.00105698720604042" />
    <parent
      link="base_link" />
    <child
      link="LHIPp" />
    <axis
      xyz="0.999996607597238 0.00238066905331354 -0.00105698101866503" />
    <limit
      lower="-0.75"
      upper="1.57"
      effort="0"
      velocity="0" />
  </joint>
  <link
    name="LHIPy">
    <inertial>
      <origin
        xyz="-0.00853936372152238 -0.034479749984876 -0.0158346788164383"
        rpy="0 0 0" />
      <mass
        value="0.00796" />
      <inertia
        ixx="7.44326056980034E-07"
        ixy="-9.73813296686781E-08"
        ixz="-3.43907565334525E-08"
        iyy="5.40139866980604E-07"
        iyz="1.94587609407361E-07"
        izz="3.84699652962392E-07" />
    </inertial>
    <visual>
      <origin
        xyz="0 0 0"
        rpy="0 0 0" />
      <geometry>
        <mesh
          filename="package://V3/meshes/LHIPy.STL" />
      </geometry>
      <material
        name="">
        <color
          rgba="0.792156862745098 0.819607843137255 0.933333333333333 1" />
      </material>
    </visual>
    <collision>
      <origin
        xyz="0 0 0"
        rpy="0 0 0" />
      <geometry>
        <mesh
          filename="package://V3/meshes/LHIPy.STL" />
      </geometry>
    </collision>
  </link>
  <joint
    name="LHIPy"
    type="revolute">
    <origin
      xyz="-0.0320750638195193 5.58786960413097E-05 -6.61143784816639E-05"
      rpy="0 0 0" />
    <parent
      link="LHIPp" />
    <child
      link="LHIPy" />
    <axis
      xyz="-0.00105698401394266 0 -0.999999441392241" />
    <limit
      lower="-0.14"
      upper="1.39"
      effort="0"
      velocity="0" />
  </joint>
  <link
    name="LHIPr">
    <inertial>
      <origin
        xyz="-0.000643093596794687 -0.0646139643461603 -0.00501142221648341"
        rpy="0 0 0" />
      <mass
        value="0.21670" />
      <inertia
        ixx="5.27058556255585E-06"
        ixy="4.82411876748748E-09"
        ixz="-1.90476290223497E-07"
        iyy="3.88872298790152E-06"
        iyz="1.83876643853407E-07"
        izz="5.30321916922738E-06" />
    </inertial>
    <visual>
      <origin
        xyz="0 0 0"
        rpy="0 0 0" />
      <geometry>
        <mesh
          filename="package://V3/meshes/LHIPr.STL" />
      </geometry>
      <material
        name="">
        <color
          rgba="0.792156862745098 0.819607843137255 0.933333333333333 1" />
      </material>
    </visual>
    <collision>
      <origin
        xyz="0 0 0"
        rpy="0 0 0" />
      <geometry>
        <mesh
          filename="package://V3/meshes/LHIPr.STL" />
      </geometry>
    </collision>
  </link>
  <joint
    name="LHIPr"
    type="revolute">
    <origin
      xyz="-0.00599999999999999 -0.0471395866467453 0"
      rpy="-0.00638182024801053 0.000817654768536195 -0.0357625594173677" />
    <parent
      link="LHIPy" />
    <child
      link="LHIPr" />
    <axis
      xyz="0.0357549248016149 -0.999340423672473 -0.00634846174690098" />
    <limit
      lower="-1.47"
      upper="0.22"
      effort="0"
      velocity="0" />
  </joint>
  <link
    name="LKNEEp">
    <inertial>
      <origin
        xyz="-0.0109855620258126 -0.039301433173679 -0.00773020940982851"
        rpy="0 0 0" />
      <mass
        value="0.13866" />
      <inertia
        ixx="5.89446081339765E-06"
        ixy="4.34439651059314E-08"
        ixz="4.87026069539692E-08"
        iyy="1.84730677092009E-06"
        iyz="-1.05630153101691E-08"
        izz="4.82704520180029E-06" />
    </inertial>
    <visual>
      <origin
        xyz="0 0 0"
        rpy="0 0 0" />
      <geometry>
        <mesh
          filename="package://V3/meshes/LKNEEp.STL" />
      </geometry>
      <material
        name="">
        <color
          rgba="0.792156862745098 0.819607843137255 0.933333333333333 1" />
      </material>
    </visual>
    <collision>
      <origin
        xyz="0 0 0"
        rpy="0 0 0" />
      <geometry>
        <mesh
          filename="package://V3/meshes/LKNEEp.STL" />
      </geometry>
    </collision>
  </link>
  <joint
    name="LKNEEp"
    type="revolute">
    <origin
      xyz="0.00331736917785609 -0.0927195695347002 -0.00059901534231738"
      rpy="0.0200711164823325 1.16674707094465E-05 0.0357633425271319" />
    <parent
      link="LHIPr" />
    <child
      link="LKNEEp" />
    <axis
      xyz="1 0 0" />
    <limit
      lower="-1.57"
      upper="0.29"
      effort="0"
      velocity="0" />
  </joint>
  <link
    name="LANKLEp">
    <inertial>
      <origin
        xyz="-0.00350000178252131 -1.78252146376678E-09 1.78252139741361E-09"
        rpy="0 0 0" />
      <mass
        value="0.00289" />
      <inertia
        ixx="3.47835662925479E-08"
        ixy="9.19277352029751E-21"
        ixz="-9.17596066963795E-21"
        iyy="3.47835662925479E-08"
        iyz="-9.22115097479973E-21"
        izz="3.47835662925479E-08" />
    </inertial>
    <visual>
      <origin
        xyz="0 0 0"
        rpy="0 0 0" />
      <geometry>
        <mesh
          filename="package://V3/meshes/LANKLEp.STL" />
      </geometry>
      <material
        name="">
        <color
          rgba="0.776470588235294 0.756862745098039 0.737254901960784 1" />
      </material>
    </visual>
    <collision>
      <origin
        xyz="0 0 0"
        rpy="0 0 0" />
      <geometry>
        <mesh
          filename="package://V3/meshes/LANKLEp.STL" />
      </geometry>
    </collision>
  </link>
  <joint
    name="LANKLEp"
    type="revolute">
    <origin
      xyz="0 -0.14 0"
      rpy="0.0029502 0 0" />
    <parent
      link="LKNEEp" />
    <child
      link="LANKLEp" />
    <axis
      xyz="-1 0 0" />
    <limit
      lower="-0.43"
      upper="0.06"
      effort="0"
      velocity="0" />
  </joint>
  <link
    name="LANKLEy">
    <inertial>
      <origin
        xyz="-0.00349943343558676 -0.0174823136885468 -0.0244034793992341"
        rpy="0 0 0" />
      <mass
        value="0.02488" />
      <inertia
        ixx="5.0805809590663E-06"
        ixy="-2.2351529651608E-15"
        ixz="1.10261943583047E-14"
        iyy="6.07928686402194E-06"
        iyz="-2.76049804528683E-09"
        izz="1.17720026301645E-06" />
    </inertial>
    <visual>
      <origin
        xyz="0 0 0"
        rpy="0 0 0" />
      <geometry>
        <mesh
          filename="package://V3/meshes/LANKLEy.STL" />
      </geometry>
      <material
        name="">
        <color
          rgba="0.792156862745098 0.819607843137255 0.933333333333333 1" />
      </material>
    </visual>
    <collision>
      <origin
        xyz="0 0 0"
        rpy="0 0 0" />
      <geometry>
        <mesh
          filename="package://V3/meshes/LANKLEy.STL" />
      </geometry>
    </collision>
  </link>
  <joint
    name="LANKLEy"
    type="revolute">
    <origin
      xyz="0 0 0"
      rpy="0 0 -0.017993" />
    <parent
      link="LANKLEp" />
    <child
      link="LANKLEy" />
    <axis
      xyz="0 0 1" />
    <limit
      lower="-0.17"
      upper="0.17"
      effort="0"
      velocity="0" />
  </joint>
</robot>