<?xml version="1.0" encoding="utf-8"?>
<!-- This URDF was automatically created by SolidWorks to URDF Exporter! Originally created by Stephen Brawner (brawner@gmail.com) 
     Commit Version: 1.6.0-4-g7f85cfe  Build Version: 1.6.7995.38578
     For more information, please see http://wiki.ros.org/sw_urdf_exporter -->
<robot
  name="URDF_Humanoid_Legs_V3.SLDASM">
  <link
    name="base_link">
    <inertial>
      <origin
        xyz="0.0144455075455517 -0.00394801696589402 0.0219644780522235"
        rpy="0 0 0" />
      <mass
        value="6.0" />
      <inertia
        ixx="6.35875327338872E-05"
        ixy="-6.58066667742006E-07"
        ixz="-2.28141316036594E-08"
        iyy="5.21696312321936E-05"
        iyz="-4.57383057174044E-07"
        izz="6.36322141016105E-05" />
    </inertial>
    <visual>
      <origin
        xyz="0 0 0"
        rpy="0 0 0" />
      <geometry>
        <mesh
          filename="package://URDF_Humanoid_Legs_V3.SLDASM/meshes/base_link.STL" />
      </geometry>
      <material
        name="">
        <color
          rgba="1 1 1 1" />
      </material>
    </visual>
    <collision>
      <origin
        xyz="0 0 0"
        rpy="0 0 0" />
      <geometry>
        <mesh
          filename="package://URDF_Humanoid_Legs_V3.SLDASM/meshes/base_link.STL" />
      </geometry>
    </collision>
  </link>
  <link
    name="pelvis_link">
    <inertial>
      <origin
        xyz="0.0059686813588107 -0.0264104697868881 0.0264693755768613"
        rpy="0 0 0" />
      <mass
        value="0.76" />
      <inertia
        ixx="2.46933165009716E-05"
        ixy="-1.15599067753389E-08"
        ixz="3.88527795234152E-10"
        iyy="8.73689950962123E-05"
        iyz="2.23030846176424E-08"
        izz="8.87648575451081E-05" />
    </inertial>
    <visual>
      <origin
        xyz="0 0 0"
        rpy="0 0 0" />
      <geometry>
        <mesh
          filename="package://URDF_Humanoid_Legs_V3.SLDASM/meshes/pelvis_link.STL" />
      </geometry>
      <material
        name="">
        <color
          rgba="1 1 1 1" />
      </material>
    </visual>
    <collision>
      <origin
        xyz="0 0 0"
        rpy="0 0 0" />
      <geometry>
        <mesh
          filename="package://URDF_Humanoid_Legs_V3.SLDASM/meshes/pelvis_link.STL" />
      </geometry>
    </collision>
  </link>
  <joint
    name="pelvis_link"
    type="revolute">
    <origin
      xyz="0.0037417 0.021916 -0.095648"
      rpy="1.6179 0.051536 0.13434" />
    <parent
      link="base_link" />
    <child
      link="pelvis_link" />
    <axis
      xyz="0 0 -1" />
    <limit
      lower="-1.57"
      upper="1.57"
      effort="0"
      velocity="0" />
  </joint>
  <link
    name="RHIPp">
    <inertial>
      <origin
        xyz="0.0162877786402017 -0.0133630272371528 0.0127927816829681"
        rpy="0 0 0" />
      <mass
        value="0.08627" />
      <inertia
        ixx="1.36413523692765E-05"
        ixy="1.54973998709477E-06"
        ixz="2.89382212231118E-06"
        iyy="1.29568407070941E-05"
        iyz="-3.52554247995872E-06"
        izz="5.98007316347542E-06" />
    </inertial>
    <visual>
      <origin
        xyz="0 0 0"
        rpy="0 0 0" />
      <geometry>
        <mesh
          filename="package://URDF_Humanoid_Legs_V3.SLDASM/meshes/RHIPp.STL" />
      </geometry>
      <material
        name="">
        <color
          rgba="0.866666666666667 0.909803921568627 1 1" />
      </material>
    </visual>
    <collision>
      <origin
        xyz="0 0 0"
        rpy="0 0 0" />
      <geometry>
        <mesh
          filename="package://URDF_Humanoid_Legs_V3.SLDASM/meshes/RHIPp.STL" />
      </geometry>
    </collision>
  </link>
  <joint
    name="RHIPp"
    type="revolute">
    <origin
      xyz="-0.082912 -0.027004 0.048375"
      rpy="0.54799 0 0" />
    <parent
      link="pelvis_link" />
    <child
      link="RHIPp" />
    <axis
      xyz="1 0 0" />
    <limit
      lower="-3.14"
      upper="0.79"
      effort="0"
      velocity="0" />
  </joint>
  <link
    name="RHIPy">
    <inertial>
      <origin
        xyz="-0.00372207331369154 -0.0312537397604348 0.0232286445323699"
        rpy="0 0 0" />
      <mass
        value="0.01934" />
      <inertia
        ixx="5.4825030829968E-06"
        ixy="-1.4470005450136E-06"
        ixz="-8.0850882236902E-07"
        iyy="3.98327497583321E-06"
        iyz="-1.49821709259362E-06"
        izz="4.01650939723747E-06" />
    </inertial>
    <visual>
      <origin
        xyz="0 0 0"
        rpy="0 0 0" />
      <geometry>
        <mesh
          filename="package://URDF_Humanoid_Legs_V3.SLDASM/meshes/RHIPy.STL" />
      </geometry>
      <material
        name="">
        <color
          rgba="1 1 1 1" />
      </material>
    </visual>
    <collision>
      <origin
        xyz="0 0 0"
        rpy="0 0 0" />
      <geometry>
        <mesh
          filename="package://URDF_Humanoid_Legs_V3.SLDASM/meshes/RHIPy.STL" />
      </geometry>
    </collision>
  </link>
  <joint
    name="RHIPy"
    type="revolute">
    <origin
      xyz="0 0 0"
      rpy="0 0 0" />
    <parent
      link="RHIPp" />
    <child
      link="RHIPy" />
    <axis
      xyz="0 -0.52097 -0.85357" />
    <limit
      lower="-0.7"
      upper="1.6"
      effort="0"
      velocity="0" />
  </joint>
  <link
    name="RHIPr">
    <inertial>
      <origin
        xyz="-0.00852993333161804 -0.00430333778194963 0.040906409975098"
        rpy="0 0 0" />
      <mass
        value="0.21427" />
      <inertia
        ixx="3.20005361109862E-05"
        ixy="-2.13314061599409E-07"
        ixz="-2.70133717677379E-06"
        iyy="2.93884998791946E-05"
        iyz="-2.31061547737118E-07"
        izz="9.44823504652317E-06" />
    </inertial>
    <visual>
      <origin
        xyz="0 0 0"
        rpy="0 0 0" />
      <geometry>
        <mesh
          filename="package://URDF_Humanoid_Legs_V3.SLDASM/meshes/RHIPr.STL" />
      </geometry>
      <material
        name="">
        <color
          rgba="1 1 1 1" />
      </material>
    </visual>
    <collision>
      <origin
        xyz="0 0 0"
        rpy="0 0 0" />
      <geometry>
        <mesh
          filename="package://URDF_Humanoid_Legs_V3.SLDASM/meshes/RHIPr.STL" />
      </geometry>
    </collision>
  </link>
  <joint
    name="RHIPr"
    type="revolute">
    <origin
      xyz="-0.0019151 -0.17144 0.10276"
      rpy="2.1188 0 3.1416" />
    <parent
      link="RHIPy" />
    <child
      link="RHIPr" />
    <axis
      xyz="0 0 1" />
    <limit
      lower="-1.7"
      upper="0.52"
      effort="0"
      velocity="0" />
  </joint>
  <link
    name="RKNEEp">
    <inertial>
      <origin
        xyz="-0.0211592759865698 -0.0618738354626966 0.036368918248475"
        rpy="0 0 0" />
      <mass
        value="0.14480" />
      <inertia
        ixx="6.26154149215685E-05"
        ixy="-9.75730519291046E-07"
        ixz="5.54214165968051E-07"
        iyy="1.80067075511607E-05"
        iyz="2.36965565467955E-05"
        izz="4.85700339841872E-05" />
    </inertial>
    <visual>
      <origin
        xyz="0 0 0"
        rpy="0 0 0" />
      <geometry>
        <mesh
          filename="package://URDF_Humanoid_Legs_V3.SLDASM/meshes/RKNEEp.STL" />
      </geometry>
      <material
        name="">
        <color
          rgba="1 1 1 1" />
      </material>
    </visual>
    <collision>
      <origin
        xyz="0 0 0"
        rpy="0 0 0" />
      <geometry>
        <mesh
          filename="package://URDF_Humanoid_Legs_V3.SLDASM/meshes/RKNEEp.STL" />
      </geometry>
    </collision>
  </link>
  <joint
    name="RKNEEp"
    type="revolute">
    <origin
      xyz="-0.0145 0.0005 0"
      rpy="2.0938 -0.031615 -3.1045" />
    <parent
      link="RHIPr" />
    <child
      link="RKNEEp" />
    <axis
      xyz="0.99881 -0.0088645 0.047869" />
    <limit
      lower="-0.79"
      upper="2.6"
      effort="0"
      velocity="0" />
  </joint>
  <link
    name="RANKLEp">
    <inertial>
      <origin
        xyz="-1.85040874983722E-09 -1.84960408100565E-09 0.00500000184962268"
        rpy="0 0 0" />
      <mass
        value="0.00590" />
      <inertia
        ixx="3.7794522268695E-08"
        ixy="6.93549584595086E-21"
        ixz="-6.80459451401434E-21"
        iyy="3.77945222686951E-08"
        iyz="-6.85709463351732E-21"
        izz="3.77945222686951E-08" />
    </inertial>
    <visual>
      <origin
        xyz="0 0 0"
        rpy="0 0 0" />
      <geometry>
        <mesh
          filename="package://URDF_Humanoid_Legs_V3.SLDASM/meshes/RANKLEp.STL" />
      </geometry>
      <material
        name="">
        <color
          rgba="0.866666666666667 0.909803921568627 1 1" />
      </material>
    </visual>
    <collision>
      <origin
        xyz="0 0 0"
        rpy="0 0 0" />
      <geometry>
        <mesh
          filename="package://URDF_Humanoid_Legs_V3.SLDASM/meshes/RANKLEp.STL" />
      </geometry>
    </collision>
  </link>
  <joint
    name="RANKLEp"
    type="revolute">
    <origin
      xyz="-0.020463 -0.17739 0.10166"
      rpy="-3.046 1.0455 -1.4969" />
    <parent
      link="RKNEEp" />
    <child
      link="RANKLEp" />
    <axis
      xyz="0 -1 0" />
    <limit
      lower="-1.4"
      upper="1.4"
      effort="0"
      velocity="0" />
  </joint>
  <link
    name="RANKLEy">
    <inertial>
      <origin
        xyz="8.16258449720664E-11 0.0407877084718919 0.0214005607738913"
        rpy="0 0 0" />
      <mass
        value="0.14942" />
      <inertia
        ixx="8.38514534613717E-05"
        ixy="5.21580961353776E-15"
        ixz="1.132655874317E-14"
        iyy="1.3744091708472E-05"
        iyz="-1.13165531851637E-08"
        izz="9.70905380754172E-05" />
    </inertial>
    <visual>
      <origin
        xyz="0 0 0"
        rpy="0 0 0" />
      <geometry>
        <mesh
          filename="package://URDF_Humanoid_Legs_V3.SLDASM/meshes/RANKLEy.STL" />
      </geometry>
      <material
        name="">
        <color
          rgba="1 1 1 1" />
      </material>
    </visual>
    <collision>
      <origin
        xyz="0 0 0"
        rpy="0 0 0" />
      <geometry>
        <mesh
          filename="package://URDF_Humanoid_Legs_V3.SLDASM/meshes/RANKLEy.STL" />
      </geometry>
    </collision>
  </link>
  <joint
    name="RANKLEy"
    type="revolute">
    <origin
      xyz="-0.00024303 0 0.005"
      rpy="3.1416 0 -1.5708" />
    <parent
      link="RANKLEp" />
    <child
      link="RANKLEy" />
    <axis
      xyz="0 1 0" />
    <limit
      lower="-0.52"
      upper="0.52"
      effort="0"
      velocity="0" />
  </joint>
  <link
    name="LHIPp">
    <inertial>
      <origin
        xyz="0.00506577352286371 -0.0175468311848719 -0.0180828985978941"
        rpy="0 0 0" />
      <mass
        value="0.08627" />
      <inertia
        ixx="4.4735443752088E-06"
        ixy="-2.66504529533205E-06"
        ixz="1.42372120746739E-06"
        iyy="1.38696354509355E-05"
        iyz="4.37730477214756E-08"
        izz="1.42350863531616E-05" />
    </inertial>
    <visual>
      <origin
        xyz="0 0 0"
        rpy="0 0 0" />
      <geometry>
        <mesh
          filename="package://URDF_Humanoid_Legs_V3.SLDASM/meshes/LHIPp.STL" />
      </geometry>
      <material
        name="">
        <color
          rgba="0.866666666666667 0.909803921568627 1 1" />
      </material>
    </visual>
    <collision>
      <origin
        xyz="0 0 0"
        rpy="0 0 0" />
      <geometry>
        <mesh
          filename="package://URDF_Humanoid_Legs_V3.SLDASM/meshes/LHIPp.STL" />
      </geometry>
    </collision>
  </link>
  <joint
    name="LHIPp"
    type="revolute">
    <origin
      xyz="0.095548 -0.027004 0.04725"
      rpy="2.8498 -1.5708 1.847" />
    <parent
      link="pelvis_link" />
    <child
      link="LHIPp" />
    <axis
      xyz="0 1 0" />
    <limit
      lower="-3.14"
      upper="0.79"
      effort="0"
      velocity="0" />
  </joint>
  <link
    name="LHIPy">
    <inertial>
      <origin
        xyz="0.000407510080643672 0.00263808681897457 -0.0398992326314391"
        rpy="0 0 0" />
      <mass
        value="0.01934" />
      <inertia
        ixx="1.56132626802381E-05"
        ixy="7.07458995414407E-06"
        ixz="-2.90668462732435E-06"
        iyy="3.24353194636072E-05"
        iyz="4.47644236574541E-06"
        izz="3.17288201922621E-05" />
    </inertial>
    <visual>
      <origin
        xyz="0 0 0"
        rpy="0 0 0" />
      <geometry>
        <mesh
          filename="package://URDF_Humanoid_Legs_V3.SLDASM/meshes/LHIPy.STL" />
      </geometry>
      <material
        name="">
        <color
          rgba="0.866666666666667 0.909803921568627 1 1" />
      </material>
    </visual>
    <collision>
      <origin
        xyz="0 0 0"
        rpy="0 0 0" />
      <geometry>
        <mesh
          filename="package://URDF_Humanoid_Legs_V3.SLDASM/meshes/LHIPy.STL" />
      </geometry>
    </collision>
  </link>
  <joint
    name="LHIPy"
    type="revolute">
    <origin
      xyz="0 0 0"
      rpy="0 0 0" />
    <parent
      link="LHIPp" />
    <child
      link="LHIPy" />
    <axis
      xyz="-1 0 0" />
    <limit
      lower="-1.6"
      upper="0.7"
      effort="0"
      velocity="0" />
  </joint>
  <link
    name="LHIPr">
    <inertial>
      <origin
        xyz="-0.00858602610093928 -0.00470614401994481 -0.0410634630964772"
        rpy="0 0 0" />
      <mass
        value="0.21427" />
      <inertia
        ixx="3.19983853255584E-05"
        ixy="-2.13601696053138E-07"
        ixz="2.70146546775301E-06"
        iyy="2.93873094391899E-05"
        iyz="2.28332283113833E-07"
        izz="9.44705371354832E-06" />
    </inertial>
    <visual>
      <origin
        xyz="0 0 0"
        rpy="0 0 0" />
      <geometry>
        <mesh
          filename="package://URDF_Humanoid_Legs_V3.SLDASM/meshes/LHIPr.STL" />
      </geometry>
      <material
        name="">
        <color
          rgba="1 1 1 1" />
      </material>
    </visual>
    <collision>
      <origin
        xyz="0 0 0"
        rpy="0 0 0" />
      <geometry>
        <mesh
          filename="package://URDF_Humanoid_Legs_V3.SLDASM/meshes/LHIPr.STL" />
      </geometry>
    </collision>
  </link>
  <joint
    name="LHIPr"
    type="revolute">
    <origin
      xyz="0.0020009 0.00086595 -0.2"
      rpy="3.1416 0 1.5708" />
    <parent
      link="LHIPy" />
    <child
      link="LHIPr" />
    <axis
      xyz="0 0 -1" />
    <limit
      lower="-0.52"
      upper="1.7"
      effort="0"
      velocity="0" />
  </joint>
  <link
    name="LKNEEp">
    <inertial>
      <origin
        xyz="0.0198943593807984 0.00129513735668229 0.0714650498121955"
        rpy="0 0 0" />
      <mass
        value="0.14480" />
      <inertia
        ixx="0.000169233198460797"
        ixy="2.48776236698737E-08"
        ixz="1.74423884604693E-06"
        iyy="0.000165987468170451"
        iyz="3.70936894431773E-06"
        izz="1.38660398030817E-05" />
    </inertial>
    <visual>
      <origin
        xyz="0 0 0"
        rpy="0 0 0" />
      <geometry>
        <mesh
          filename="package://URDF_Humanoid_Legs_V3.SLDASM/meshes/LKNEEp.STL" />
      </geometry>
      <material
        name="">
        <color
          rgba="0.866666666666667 0.909803921568627 1 1" />
      </material>
    </visual>
    <collision>
      <origin
        xyz="0 0 0"
        rpy="0 0 0" />
      <geometry>
        <mesh
          filename="package://URDF_Humanoid_Legs_V3.SLDASM/meshes/LKNEEp.STL" />
      </geometry>
    </collision>
  </link>
  <joint
    name="LKNEEp"
    type="revolute">
    <origin
      xyz="-0.0152 0 0"
      rpy="0 0 0" />
    <parent
      link="LHIPr" />
    <child
      link="LKNEEp" />
    <axis
      xyz="-1 0 0" />
    <limit
      lower="-2.6"
      upper="0.79"
      effort="0"
      velocity="0" />
  </joint>
  <link
    name="LANKLEp">
    <inertial>
      <origin
        xyz="-1.84958448556927E-09 -1.84959818294583E-09 0.00500000184879898"
        rpy="0 0 0" />
      <mass
        value="0.00590" />
      <inertia
        ixx="3.77945222686952E-08"
        ixy="6.89341303228723E-21"
        ixz="-6.77853832471892E-21"
        iyy="3.77945222686951E-08"
        iyz="-6.84698752040769E-21"
        izz="3.77945222686952E-08" />
    </inertial>
    <visual>
      <origin
        xyz="0 0 0"
        rpy="0 0 0" />
      <geometry>
        <mesh
          filename="package://URDF_Humanoid_Legs_V3.SLDASM/meshes/LANKLEp.STL" />
      </geometry>
      <material
        name="">
        <color
          rgba="0.866666666666667 0.909803921568627 1 1" />
      </material>
    </visual>
    <collision>
      <origin
        xyz="0 0 0"
        rpy="0 0 0" />
      <geometry>
        <mesh
          filename="package://URDF_Humanoid_Legs_V3.SLDASM/meshes/LANKLEp.STL" />
      </geometry>
    </collision>
  </link>
  <joint
    name="LANKLEp"
    type="revolute">
    <origin
      xyz="0.0152 0.005 0.2"
      rpy="1.5708 1.5708 0" />
    <parent
      link="LKNEEp" />
    <child
      link="LANKLEp" />
    <axis
      xyz="0 -1 0" />
    <limit
      lower="-1.4"
      upper="1.4"
      effort="0"
      velocity="0" />
  </joint>
  <link
    name="LANKLEy">
    <inertial>
      <origin
        xyz="4.79427608723881E-12 0.0376072027757355 -0.0235825366788683"
        rpy="0 0 0" />
      <mass
        value="0.14942" />
      <inertia
        ixx="8.37067999521343E-05"
        ixy="2.24378163754058E-14"
        ixz="-8.6074581708554E-15"
        iyy="1.38141738120107E-05"
        iyz="4.21765318989417E-06"
        izz="9.66362481808808E-05" />
    </inertial>
    <visual>
      <origin
        xyz="0 0 0"
        rpy="0 0 0" />
      <geometry>
        <mesh
          filename="package://URDF_Humanoid_Legs_V3.SLDASM/meshes/LANKLEy.STL" />
      </geometry>
      <material
        name="">
        <color
          rgba="1 1 1 1" />
      </material>
    </visual>
    <collision>
      <origin
        xyz="0 0 0"
        rpy="0 0 0" />
      <geometry>
        <mesh
          filename="package://URDF_Humanoid_Legs_V3.SLDASM/meshes/LANKLEy.STL" />
      </geometry>
    </collision>
  </link>
  <joint
    name="LANKLEy"
    type="revolute">
    <origin
      xyz="0 0 0"
      rpy="-1.5202 0 -1.5708" />
    <parent
      link="LANKLEp" />
    <child
      link="LANKLEy" />
    <axis
      xyz="0 -0.99872 0.050592" />
    <limit
      lower="-0.523"
      upper="0.523"
      effort="0"
      velocity="0" />
  </joint>
</robot>