<?xml version="1.0" encoding="utf-8"?>
<!-- This URDF was automatically created by SolidWorks to URDF Exporter! Originally created by Stephen Brawner (brawner@gmail.com) 
     Commit Version: 1.6.0-4-g7f85cfe  Build Version: 1.6.7995.38578
     For more information, please see http://wiki.ros.org/sw_urdf_exporter -->
<robot
  name="V4.SLDASM">
  <link
    name="base_link">
    <inertial>
      <origin
        xyz="0.000500910908733876 -0.00998629103930559 0.0173218447986229"
        rpy="0 0 0" />
      <mass
        value="0.33504" />
      <inertia
        ixx="1.97764712583923E-05"
        ixy="2.95428059624508E-09"
        ixz="-2.25102941158597E-08"
        iyy="7.26645068369103E-05"
        iyz="-1.73059202753526E-06"
        izz="6.99381839815544E-05" />
    </inertial>
    <visual>
      <origin
        xyz="0 0 0"
        rpy="0 0 0" />
      <geometry>
        <mesh
          filename="package://V4.SLDASM/meshes/base_link.STL" />
      </geometry>
      <material
        name="">
        <color
          rgba="0.792156862745098 0.819607843137255 0.933333333333333 1" />
      </material>
    </visual>
    <collision>
      <origin
        xyz="0 0 0"
        rpy="0 0 0" />
      <geometry>
        <mesh
          filename="package://V4.SLDASM/meshes/base_link.STL" />
      </geometry>
    </collision>
  </link>
  <link
    name="Waist">
    <inertial>
      <origin
        xyz="-8.30608238439057E-11 0.0324696863156453 0.00531795471648416"
        rpy="0 0 0" />
      <mass
        value="0.0152478549678287" />
      <inertia
        ixx="9.63125992413617E-06"
        ixy="-4.11230545715372E-14"
        ixz="-1.78226542256735E-14"
        iyy="5.88153288004389E-06"
        iyz="1.47868590781889E-07"
        izz="5.40129346132741E-06" />
    </inertial>
    <visual>
      <origin
        xyz="0 0 0"
        rpy="0 0 0" />
      <geometry>
        <mesh
          filename="package://V4.SLDASM/meshes/Waist.STL" />
      </geometry>
      <material
        name="">
        <color
          rgba="1 1 1 1" />
      </material>
    </visual>
    <collision>
      <origin
        xyz="0 0 0"
        rpy="0 0 0" />
      <geometry>
        <mesh
          filename="package://V4.SLDASM/meshes/Waist.STL" />
      </geometry>
    </collision>
  </link>
  <joint
    name="Waist"
    type="fixed">
    <origin
      xyz="0.00275 0 0.04211"
      rpy="1.5708 0 0" />
    <parent
      link="base_link" />
    <child
      link="Waist" />
    <axis
      xyz="0 0 0" />
    <limit
      lower="-0.52"
      upper="0.52"
      effort="0"
      velocity="0" />
  </joint>
  <link
    name="Waist_2">
    <inertial>
      <origin
        xyz="0.000488921628191946 0.158904911204199 -0.00145233666018986"
        rpy="0 0 0" />
      <mass
        value="0.66174" />
      <inertia
        ixx="0.000601071923731556"
        ixy="1.2892451729049E-06"
        ixz="2.54284162583461E-05"
        iyy="0.000814982910525989"
        iyz="1.10939073171587E-05"
        izz="0.00113760922496659" />
    </inertial>
    <visual>
      <origin
        xyz="0 0 0"
        rpy="0 0 0" />
      <geometry>
        <mesh
          filename="package://V4.SLDASM/meshes/Waist_2.STL" />
      </geometry>
      <material
        name="">
        <color
          rgba="0.792156862745098 0.819607843137255 0.933333333333333 1" />
      </material>
    </visual>
    <collision>
      <origin
        xyz="0 0 0"
        rpy="0 0 0" />
      <geometry>
        <mesh
          filename="package://V4.SLDASM/meshes/Waist_2.STL" />
      </geometry>
    </collision>
  </link>
  <joint
    name="Waist_2"
    type="revolute">
    <origin
      xyz="0 0.021605 0.00067"
      rpy="-3.1416 0 3.1386" />
    <parent
      link="Waist" />
    <child
      link="Waist_2" />
    <axis
      xyz="-0.0029703 -1 0" />
    <limit
      lower="-6.28"
      upper="6.28"
      effort="0"
      velocity="0" />
  </joint>
  <link
    name="RSDp">
    <inertial>
      <origin
        xyz="0.029365339777939 -0.0145376874428952 -0.0120536310806074"
        rpy="0 0 0" />
      <mass
        value="0.02666" />
      <inertia
        ixx="2.4185481628886E-06"
        ixy="4.81669677091078E-08"
        ixz="3.69839487042427E-07"
        iyy="2.62122104926124E-06"
        iyz="-1.15971922654066E-07"
        izz="8.26141091388542E-07" />
    </inertial>
    <visual>
      <origin
        xyz="0 0 0"
        rpy="0 0 0" />
      <geometry>
        <mesh
          filename="package://V4.SLDASM/meshes/RSDp.STL" />
      </geometry>
      <material
        name="">
        <color
          rgba="0.792156862745098 0.819607843137255 0.933333333333333 1" />
      </material>
    </visual>
    <collision>
      <origin
        xyz="0 0 0"
        rpy="0 0 0" />
      <geometry>
        <mesh
          filename="package://V4.SLDASM/meshes/RSDp.STL" />
      </geometry>
    </collision>
  </link>
  <joint
    name="RSDp"
    type="revolute">
    <origin
      xyz="-0.081055 0.13392 0.003366"
      rpy="3.0698 -0.053568 3.1386" />
    <parent
      link="Waist_2" />
    <child
      link="RSDp" />
    <axis
      xyz="1 0 0" />
    <limit
      lower="-1.57"
      upper="1.57"
      effort="0"
      velocity="0" />
  </joint>
  <link
    name="RSDy">
    <inertial>
      <origin
        xyz="-0.00268951566935521 -0.0432907123235495 -0.0121725877314745"
        rpy="0 0 0" />
      <mass
        value="0.00796" />
      <inertia
        ixx="7.44326056980046E-07"
        ixy="9.46622369551179E-08"
        ixz="4.12905364173831E-08"
        iyy="5.11482673925875E-07"
        iyz="2.03709556090736E-07"
        izz="4.13356846017119E-07" />
    </inertial>
    <visual>
      <origin
        xyz="0 0 0"
        rpy="0 0 0" />
      <geometry>
        <mesh
          filename="package://V4.SLDASM/meshes/RSDy.STL" />
      </geometry>
      <material
        name="">
        <color
          rgba="0.792156862745098 0.819607843137255 0.933333333333333 1" />
      </material>
    </visual>
    <collision>
      <origin
        xyz="0 0 0"
        rpy="0 0 0" />
      <geometry>
        <mesh
          filename="package://V4.SLDASM/meshes/RSDy.STL" />
      </geometry>
    </collision>
  </link>
  <joint
    name="RSDy"
    type="revolute">
    <origin
      xyz="0.047234 0.01 -0.00611"
      rpy="0 0 0" />
    <parent
      link="RSDp" />
    <child
      link="RSDy" />
    <axis
      xyz="0 0.071764 -0.99742" />
    <limit
      lower="-1.39"
      upper="0.14"
      effort="0"
      velocity="0" />
  </joint>
  <link
    name="RSDr">
    <inertial>
      <origin
        xyz="-0.000648993351435478 -0.0644490658095404 -0.00501037463776728"
        rpy="0 0 0" />
      <mass
        value="0.21670" />
      <inertia
        ixx="5.2705855755284E-06"
        ixy="4.82411697262527E-09"
        ixz="-1.90476291295014E-07"
        iyy="3.88872299888649E-06"
        iyz="1.83876643864369E-07"
        izz="5.30321918043652E-06" />
    </inertial>
    <visual>
      <origin
        xyz="0 0 0"
        rpy="0 0 0" />
      <geometry>
        <mesh
          filename="package://V4.SLDASM/meshes/RSDr.STL" />
      </geometry>
      <material
        name="">
        <color
          rgba="0.792156862745098 0.819607843137255 0.933333333333333 1" />
      </material>
    </visual>
    <collision>
      <origin
        xyz="0 0 0"
        rpy="0 0 0" />
      <geometry>
        <mesh
          filename="package://V4.SLDASM/meshes/RSDr.STL" />
      </geometry>
    </collision>
  </link>
  <joint
    name="RSDr"
    type="fixed">
    <origin
      xyz="-0.0052192 -0.057271 0.0026804"
      rpy="3.0635 0.002804 -3.1059" />
    <parent
      link="RSDy" />
    <child
      link="RSDr" />
    <axis
      xyz="0 0 0" />
    <limit
      lower="-0.22"
      upper="1.47"
      effort="0"
      velocity="0" />
  </joint>
  <link
    name="RARMp">
    <inertial>
      <origin
        xyz="-0.0109855620136424 -0.0393014331349118 -0.00773020942152065"
        rpy="0 0 0" />
      <mass
        value="0.13866" />
      <inertia
        ixx="5.8944608141404E-06"
        ixy="4.34439663989622E-08"
        ixz="4.87026070269323E-08"
        iyy="1.84730677144131E-06"
        iyz="-1.05630143241146E-08"
        izz="4.82704520175826E-06" />
    </inertial>
    <visual>
      <origin
        xyz="0 0 0"
        rpy="0 0 0" />
      <geometry>
        <mesh
          filename="package://V4.SLDASM/meshes/RARMp.STL" />
      </geometry>
      <material
        name="">
        <color
          rgba="0.792156862745098 0.819607843137255 0.933333333333333 1" />
      </material>
    </visual>
    <collision>
      <origin
        xyz="0 0 0"
        rpy="0 0 0" />
      <geometry>
        <mesh
          filename="package://V4.SLDASM/meshes/RARMp.STL" />
      </geometry>
    </collision>
  </link>
  <joint
    name="RARMp"
    type="revolute">
    <origin
      xyz="0.0033115 -0.092555 -0.00059797"
      rpy="0.0063485 1.1667E-05 0.035763" />
    <parent
      link="RSDr" />
    <child
      link="RARMp" />
    <axis
      xyz="1 0 0" />
    <limit
      lower="-2.26"
      upper="0.29"
      effort="0"
      velocity="0" />
  </joint>
  <link
    name="RARMAP">
    <inertial>
      <origin
        xyz="-1.68452360393978E-09 1.782521449889E-09 1.87540552878951E-09"
        rpy="0 0 0" />
      <mass
        value="0.00289" />
      <inertia
        ixx="3.47835662925469E-08"
        ixy="-8.69318646394787E-21"
        ixz="-9.15047848596362E-21"
        iyy="3.47835662925478E-08"
        iyz="9.64881793526577E-21"
        izz="3.47835662925488E-08" />
    </inertial>
    <visual>
      <origin
        xyz="0 0 0"
        rpy="0 0 0" />
      <geometry>
        <mesh
          filename="package://V4.SLDASM/meshes/RARMAP.STL" />
      </geometry>
      <material
        name="">
        <color
          rgba="0.776470588235294 0.756862745098039 0.737254901960784 1" />
      </material>
    </visual>
    <collision>
      <origin
        xyz="0 0 0"
        rpy="0 0 0" />
      <geometry>
        <mesh
          filename="package://V4.SLDASM/meshes/RARMAP.STL" />
      </geometry>
    </collision>
  </link>
  <joint
    name="RARMAP"
    type="revolute">
    <origin
      xyz="-0.0035 -0.14 0"
      rpy="-3.1416 0.053568 3.1416" />
    <parent
      link="RARMp" />
    <child
      link="RARMAP" />
    <axis
      xyz="-0.99857 0 0.053543" />
    <limit
      lower="-0.06"
      upper="1.04"
      effort="0"
      velocity="0" />
  </joint>
  <link
    name="RARMAy">
    <inertial>
      <origin
        xyz="-2.19445656091111E-10 -0.0174193425200825 0.0244034803681567"
        rpy="0 0 0" />
      <mass
        value="0.02488" />
      <inertia
        ixx="5.08058079936302E-06"
        ixy="1.68282660449513E-14"
        ixz="8.1798155085746E-15"
        iyy="6.07928688954362E-06"
        iyz="2.7604838016127E-09"
        izz="1.17720006677435E-06" />
    </inertial>
    <visual>
      <origin
        xyz="0 0 0"
        rpy="0 0 0" />
      <geometry>
        <mesh
          filename="package://V4.SLDASM/meshes/RARMAy.STL" />
      </geometry>
      <material
        name="">
        <color
          rgba="0.792156862745098 0.819607843137255 0.933333333333333 1" />
      </material>
    </visual>
    <collision>
      <origin
        xyz="0 0 0"
        rpy="0 0 0" />
      <geometry>
        <mesh
          filename="package://V4.SLDASM/meshes/RARMAy.STL" />
      </geometry>
    </collision>
  </link>
  <joint
    name="RARMAy"
    type="fixed">
    <origin
      xyz="0 0 0"
      rpy="0 0.053568 0" />
    <parent
      link="RARMAP" />
    <child
      link="RARMAy" />
    <axis
      xyz="0 0 1" />
    <limit
      lower="-0.17"
      upper="0.17"
      effort="0"
      velocity="0" />
  </joint>
  <link
    name="LSDp">
    <inertial>
      <origin
        xyz="-0.0264850638874403 -0.0161380599865885 -0.0115557024217441"
        rpy="0 0 0" />
      <mass
        value="0.02666" />
      <inertia
        ixx="2.40080281350152E-06"
        ixy="-7.45183864648936E-08"
        ixz="-3.65127810019035E-07"
        iyy="2.58667384237348E-06"
        iyz="-2.43286627561113E-07"
        izz="8.42040299247692E-07" />
    </inertial>
    <visual>
      <origin
        xyz="0 0 0"
        rpy="0 0 0" />
      <geometry>
        <mesh
          filename="package://V4.SLDASM/meshes/LSDp.STL" />
      </geometry>
      <material
        name="">
        <color
          rgba="0.792156862745098 0.819607843137255 0.933333333333333 1" />
      </material>
    </visual>
    <collision>
      <origin
        xyz="0 0 0"
        rpy="0 0 0" />
      <geometry>
        <mesh
          filename="package://V4.SLDASM/meshes/LSDp.STL" />
      </geometry>
    </collision>
  </link>
  <joint
    name="LSDp"
    type="revolute">
    <origin
      xyz="0.085975 0.13342 -0.0055901"
      rpy="3.1415 -0.052511 3.141" />
    <parent
      link="Waist_2" />
    <child
      link="LSDp" />
    <axis
      xyz="1 0.0023807 -0.001057" />
    <limit
      lower="-1.57"
      upper="1.57"
      effort="0"
      velocity="0" />
  </joint>
  <link
    name="LSDy">
    <inertial>
      <origin
        xyz="-0.00853936372152245 -0.0344797499848762 -0.0158346788164377"
        rpy="0 0 0" />
      <mass
        value="0.00796" />
      <inertia
        ixx="7.44326056980032E-07"
        ixy="-9.73813296686781E-08"
        ixz="-3.4390756533452E-08"
        iyy="5.40139866980604E-07"
        iyz="1.9458760940736E-07"
        izz="3.8469965296239E-07" />
    </inertial>
    <visual>
      <origin
        xyz="0 0 0"
        rpy="0 0 0" />
      <geometry>
        <mesh
          filename="package://V4.SLDASM/meshes/LSDy.STL" />
      </geometry>
      <material
        name="">
        <color
          rgba="0.792156862745098 0.819607843137255 0.933333333333333 1" />
      </material>
    </visual>
    <collision>
      <origin
        xyz="0 0 0"
        rpy="0 0 0" />
      <geometry>
        <mesh
          filename="package://V4.SLDASM/meshes/LSDy.STL" />
      </geometry>
    </collision>
  </link>
  <joint
    name="LSDy"
    type="revolute">
    <origin
      xyz="-0.031807 5.6518E-05 -6.6398E-05"
      rpy="0 0 0" />
    <parent
      link="LSDp" />
    <child
      link="LSDy" />
    <axis
      xyz="-0.001057 0 -1" />
    <limit
      lower="-0.14"
      upper="1.39"
      effort="0"
      velocity="0" />
  </joint>
  <link
    name="LSDr">
    <inertial>
      <origin
        xyz="-0.000141821718329591 -0.0647171132525845 -0.00916727769024185"
        rpy="0 0 0" />
      <mass
        value="0.21670" />
      <inertia
        ixx="5.32090282853741E-06"
        ixy="-4.50566976959883E-08"
        ixz="1.80744272504802E-07"
        iyy="3.89871010021898E-06"
        iyz="9.66718121994143E-08"
        izz="5.34945047353967E-06" />
    </inertial>
    <visual>
      <origin
        xyz="0 0 0"
        rpy="0 0 0" />
      <geometry>
        <mesh
          filename="package://V4.SLDASM/meshes/LSDr.STL" />
      </geometry>
      <material
        name="">
        <color
          rgba="0.792156862745098 0.819607843137255 0.933333333333333 1" />
      </material>
    </visual>
    <collision>
      <origin
        xyz="0 0 0"
        rpy="0 0 0" />
      <geometry>
        <mesh
          filename="package://V4.SLDASM/meshes/LSDr.STL" />
      </geometry>
    </collision>
  </link>
  <joint
    name="LSDr"
    type="fixed">
    <origin
      xyz="-0.006 -0.047115 0"
      rpy="3.0698 -0.001057 3.1416" />
    <parent
      link="LSDy" />
    <child
      link="LSDr" />
    <axis
      xyz="0 0 0" />
    <limit
      lower="-1.47"
      upper="0.22"
      effort="0"
      velocity="0" />
  </joint>
  <link
    name="LARMp">
    <inertial>
      <origin
        xyz="0.00720772208529306 -0.0378379502783512 -0.00744235818635386"
        rpy="0 0 0" />
      <mass
        value="0.13866" />
      <inertia
        ixx="5.94426076058107E-06"
        ixy="-4.3741422932966E-08"
        ixz="-5.50325462488361E-08"
        iyy="1.87318690292225E-06"
        iyz="-1.04237146319795E-08"
        izz="4.85241707012103E-06" />
    </inertial>
    <visual>
      <origin
        xyz="0 0 0"
        rpy="0 0 0" />
      <geometry>
        <mesh
          filename="package://V4.SLDASM/meshes/LARMp.STL" />
      </geometry>
      <material
        name="">
        <color
          rgba="0.792156862745098 0.819607843137255 0.933333333333333 1" />
      </material>
    </visual>
    <collision>
      <origin
        xyz="0 0 0"
        rpy="0 0 0" />
      <geometry>
        <mesh
          filename="package://V4.SLDASM/meshes/LARMp.STL" />
      </geometry>
    </collision>
  </link>
  <joint
    name="LARMp"
    type="revolute">
    <origin
      xyz="0 -0.092566 -0.00666"
      rpy="0.071826 0 0" />
    <parent
      link="LSDr" />
    <child
      link="LARMp" />
    <axis
      xyz="-1 0 0" />
    <limit
      lower="-0.29"
      upper="2.26"
      effort="0"
      velocity="0" />
  </joint>
  <link
    name="LARMAp">
    <inertial>
      <origin
        xyz="1.782521449889E-09 1.78252097110532E-09 -1.78252150540015E-09"
        rpy="0 0 0" />
      <mass
        value="0.00289" />
      <inertia
        ixx="3.47835662925479E-08"
        ixy="9.18833799621359E-21"
        ixz="-9.18624207482995E-21"
        iyy="3.47835662925479E-08"
        iyz="-9.18718487089677E-21"
        izz="3.47835662925479E-08" />
    </inertial>
    <visual>
      <origin
        xyz="0 0 0"
        rpy="0 0 0" />
      <geometry>
        <mesh
          filename="package://V4.SLDASM/meshes/LARMAp.STL" />
      </geometry>
      <material
        name="">
        <color
          rgba="0.776470588235294 0.756862745098039 0.737254901960784 1" />
      </material>
    </visual>
    <collision>
      <origin
        xyz="0 0 0"
        rpy="0 0 0" />
      <geometry>
        <mesh
          filename="package://V4.SLDASM/meshes/LARMAp.STL" />
      </geometry>
    </collision>
  </link>
  <joint
    name="LARMAp"
    type="revolute">
    <origin
      xyz="0 -0.14 0"
      rpy="1.5708 0 -1.5708" />
    <parent
      link="LARMp" />
    <child
      link="LARMAp" />
    <axis
      xyz="0 0 -1" />
    <limit
      lower="-0.06"
      upper="1.04"
      effort="0"
      velocity="0" />
  </joint>
  <link
    name="LARMAy">
    <inertial>
      <origin
        xyz="2.13694381634433E-10 -0.0174193425571761 -0.024403480485095"
        rpy="0 0 0" />
      <mass
        value="0.02488" />
      <inertia
        ixx="5.08058079734746E-06"
        ixy="-1.65419041124909E-14"
        ixz="8.130636537429E-15"
        iyy="6.07928688955585E-06"
        iyz="-2.76048381992039E-09"
        izz="1.17720006436185E-06" />
    </inertial>
    <visual>
      <origin
        xyz="0 0 0"
        rpy="0 0 0" />
      <geometry>
        <mesh
          filename="package://V4.SLDASM/meshes/LARMAy.STL" />
      </geometry>
      <material
        name="">
        <color
          rgba="0.792156862745098 0.819607843137255 0.933333333333333 1" />
      </material>
    </visual>
    <collision>
      <origin
        xyz="0 0 0"
        rpy="0 0 0" />
      <geometry>
        <mesh
          filename="package://V4.SLDASM/meshes/LARMAy.STL" />
      </geometry>
    </collision>
  </link>
  <joint
    name="LARMAy"
    type="fixed">
    <origin
      xyz="0 0 0"
      rpy="-1.5708 1.5708 0" />
    <parent
      link="LARMAp" />
    <child
      link="LARMAy" />
    <axis
      xyz="0 0 1" />
    <limit
      lower="-0.17"
      upper="0.17"
      effort="0"
      velocity="0" />
  </joint>
  <link
    name="RHIPp">
    <inertial>
      <origin
        xyz="0.0295665493479005 -0.0145376874433172 -0.0120536310802667"
        rpy="0 0 0" />
      <mass
        value="0.02666" />
      <inertia
        ixx="2.41854816289442E-06"
        ixy="4.8166967734081E-08"
        ixz="3.69839487107744E-07"
        iyy="2.62122104924701E-06"
        iyz="-1.1597192265796E-07"
        izz="8.26141091389484E-07" />
    </inertial>
    <visual>
      <origin
        xyz="0 0 0"
        rpy="0 0 0" />
      <geometry>
        <mesh
          filename="package://V4.SLDASM/meshes/RHIPp.STL" />
      </geometry>
      <material
        name="">
        <color
          rgba="0.792156862745098 0.819607843137255 0.933333333333333 1" />
      </material>
    </visual>
    <collision>
      <origin
        xyz="0 0 0"
        rpy="0 0 0" />
      <geometry>
        <mesh
          filename="package://V4.SLDASM/meshes/RHIPp.STL" />
      </geometry>
    </collision>
  </link>
  <joint
    name="RHIPp"
    type="revolute">
    <origin
      xyz="0.017714 0 0"
      rpy="1.499 0 0" />
    <parent
      link="base_link" />
    <child
      link="RHIPp" />
    <axis
      xyz="-1 0 0" />
    <limit
      lower="-1.57"
      upper="1.57"
      effort="0"
      velocity="0" />
  </joint>
  <link
    name="RHIPy">
    <inertial>
      <origin
        xyz="-0.00268951566935544 -0.0432907123235494 -0.0121725877314746"
        rpy="0 0 0" />
      <mass
        value="0.00796" />
      <inertia
        ixx="7.44326056980044E-07"
        ixy="9.46622369551162E-08"
        ixz="4.12905364173838E-08"
        iyy="5.11482673925872E-07"
        iyz="2.03709556090734E-07"
        izz="4.13356846017117E-07" />
    </inertial>
    <visual>
      <origin
        xyz="0 0 0"
        rpy="0 0 0" />
      <geometry>
        <mesh
          filename="package://V4.SLDASM/meshes/RHIPy.STL" />
      </geometry>
      <material
        name="">
        <color
          rgba="0.792156862745098 0.819607843137255 0.933333333333333 1" />
      </material>
    </visual>
    <collision>
      <origin
        xyz="0 0 0"
        rpy="0 0 0" />
      <geometry>
        <mesh
          filename="package://V4.SLDASM/meshes/RHIPy.STL" />
      </geometry>
    </collision>
  </link>
  <joint
    name="RHIPy"
    type="revolute">
    <origin
      xyz="0.047436 0.01 -0.00611"
      rpy="0 0 0" />
    <parent
      link="RHIPp" />
    <child
      link="RHIPy" />
    <axis
      xyz="0 0.071764 -0.99742" />
    <limit
      lower="-1.39"
      upper="0.14"
      effort="0"
      velocity="0" />
  </joint>
  <link
    name="RHIPr">
    <inertial>
      <origin
        xyz="-0.000141821553682246 -0.0645546760091016 -0.00915559046551466"
        rpy="0 0 0" />
      <mass
        value="0.21670" />
      <inertia
        ixx="5.32090280918624E-06"
        ixy="-4.50567007702022E-08"
        ixz="1.80744274836868E-07"
        iyy="3.89871007897009E-06"
        iyz="9.6671813958189E-08"
        izz="5.34945045361263E-06" />
    </inertial>
    <visual>
      <origin
        xyz="0 0 0"
        rpy="0 0 0" />
      <geometry>
        <mesh
          filename="package://V4.SLDASM/meshes/RHIPr.STL" />
      </geometry>
      <material
        name="">
        <color
          rgba="0.792156862745098 0.819607843137255 0.933333333333333 1" />
      </material>
    </visual>
    <collision>
      <origin
        xyz="0 0 0"
        rpy="0 0 0" />
      <geometry>
        <mesh
          filename="package://V4.SLDASM/meshes/RHIPr.STL" />
      </geometry>
    </collision>
  </link>
  <joint
    name="RHIPr"
    type="fixed">
    <origin
      xyz="-0.0052192 -0.057244 0.0026823"
      rpy="0 0 0" />
    <parent
      link="RHIPy" />
    <child
      link="RHIPr" />
    <axis
      xyz="0 0 0" />
    <limit
      lower="-0.22"
      upper="1.47"
      effort="0"
      velocity="0" />
  </joint>
  <link
    name="RKNEEP">
    <inertial>
      <origin
        xyz="0.00720772207709151 -0.0378379504038629 -0.00744235817106063"
        rpy="0 0 0" />
      <mass
        value="0.13866" />
      <inertia
        ixx="5.94426076092898E-06"
        ixy="-4.37414228336997E-08"
        ixz="-5.50325465299912E-08"
        iyy="1.87318690309453E-06"
        iyz="-1.04237148446069E-08"
        izz="4.85241707227756E-06" />
    </inertial>
    <visual>
      <origin
        xyz="0 0 0"
        rpy="0 0 0" />
      <geometry>
        <mesh
          filename="package://V4.SLDASM/meshes/RKNEEP.STL" />
      </geometry>
      <material
        name="">
        <color
          rgba="0.792156862745098 0.819607843137255 0.933333333333333 1" />
      </material>
    </visual>
    <collision>
      <origin
        xyz="0 0 0"
        rpy="0 0 0" />
      <geometry>
        <mesh
          filename="package://V4.SLDASM/meshes/RKNEEP.STL" />
      </geometry>
    </collision>
  </link>
  <joint
    name="RKNEEP"
    type="revolute">
    <origin
      xyz="0 -0.092403 -0.0066483"
      rpy="0.069755 0 0" />
    <parent
      link="RHIPr" />
    <child
      link="RKNEEP" />
    <axis
      xyz="-1 0 0" />
    <limit
      lower="-0.29"
      upper="2.26"
      effort="0"
      velocity="0" />
  </joint>
  <link
    name="RANKLEp">
    <inertial>
      <origin
        xyz="-1.78252151927794E-09 -1.78252151927794E-09 1.78252145872524E-09"
        rpy="0 0 0" />
      <mass
        value="0.00289" />
      <inertia
        ixx="3.47835662925478E-08"
        ixy="9.24142344123758E-21"
        ixz="-9.20427741921735E-21"
        iyy="3.47835662925479E-08"
        iyz="-9.16832773786998E-21"
        izz="3.47835662925479E-08" />
    </inertial>
    <visual>
      <origin
        xyz="0 0 0"
        rpy="0 0 0" />
      <geometry>
        <mesh
          filename="package://V4.SLDASM/meshes/RANKLEp.STL" />
      </geometry>
      <material
        name="">
        <color
          rgba="0.776470588235294 0.756862745098039 0.737254901960784 1" />
      </material>
    </visual>
    <collision>
      <origin
        xyz="0 0 0"
        rpy="0 0 0" />
      <geometry>
        <mesh
          filename="package://V4.SLDASM/meshes/RANKLEp.STL" />
      </geometry>
    </collision>
  </link>
  <joint
    name="RANKLEp"
    type="revolute">
    <origin
      xyz="0 -0.14 0"
      rpy="0 0 0" />
    <parent
      link="RKNEEP" />
    <child
      link="RANKLEp" />
    <axis
      xyz="-1 0 0" />
    <limit
      lower="-1.04"
      upper="0.06"
      effort="0"
      velocity="0" />
  </joint>
  <link
    name="RANKLEy">
    <inertial>
      <origin
        xyz="5.10645788848185E-09 -0.0174193425512699 -0.0244034804778275"
        rpy="0 0 0" />
      <mass
        value="0.02488" />
      <inertia
        ixx="5.08058079768079E-06"
        ixy="-1.58607064343413E-14"
        ixz="7.9046259153669E-13"
        iyy="6.07928688952841E-06"
        iyz="-2.76048316670902E-09"
        izz="1.17720006487251E-06" />
    </inertial>
    <visual>
      <origin
        xyz="0 0 0"
        rpy="0 0 0" />
      <geometry>
        <mesh
          filename="package://V4.SLDASM/meshes/RANKLEy.STL" />
      </geometry>
      <material
        name="">
        <color
          rgba="0.792156862745098 0.819607843137255 0.933333333333333 1" />
      </material>
    </visual>
    <collision>
      <origin
        xyz="0 0 0"
        rpy="0 0 0" />
      <geometry>
        <mesh
          filename="package://V4.SLDASM/meshes/RANKLEy.STL" />
      </geometry>
    </collision>
  </link>
  <joint
    name="RANKLEy"
    type="fixed">
    <origin
      xyz="0 0 0"
      rpy="0 0 -9.6776E-05" />
    <parent
      link="RANKLEp" />
    <child
      link="RANKLEy" />
    <axis
      xyz="0 0 1" />
    <limit
      lower="-0.17"
      upper="0.17"
      effort="0"
      velocity="0" />
  </joint>
  <link
    name="LHIPp">
    <inertial>
      <origin
        xyz="-0.0267534699752652 -0.0161386989748455 -0.0115554187206658"
        rpy="0 0 0" />
      <mass
        value="0.02666" />
      <inertia
        ixx="2.40080281351025E-06"
        ixy="-7.45183864662649E-08"
        ixz="-3.65127810022732E-07"
        iyy="2.58667384237902E-06"
        iyz="-2.43286627563919E-07"
        izz="8.4204029924739E-07" />
    </inertial>
    <visual>
      <origin
        xyz="0 0 0"
        rpy="0 0 0" />
      <geometry>
        <mesh
          filename="package://V4.SLDASM/meshes/LHIPp.STL" />
      </geometry>
      <material
        name="">
        <color
          rgba="0.792156862745098 0.819607843137255 0.933333333333333 1" />
      </material>
    </visual>
    <collision>
      <origin
        xyz="0 0 0"
        rpy="0 0 0" />
      <geometry>
        <mesh
          filename="package://V4.SLDASM/meshes/LHIPp.STL" />
      </geometry>
    </collision>
  </link>
  <joint
    name="LHIPp"
    type="revolute">
    <origin
      xyz="-0.022372 0 0"
      rpy="1.5708 0.0023807 -0.001057" />
    <parent
      link="base_link" />
    <child
      link="LHIPp" />
    <axis
      xyz="1 0.0023807 -0.001057" />
    <limit
      lower="-1.57"
      upper="1.57"
      effort="0"
      velocity="0" />
  </joint>
  <link
    name="LHIPy">
    <inertial>
      <origin
        xyz="-0.0085393637215224 -0.034479749984876 -0.0158346788164383"
        rpy="0 0 0" />
      <mass
        value="0.00796" />
      <inertia
        ixx="7.44326056980034E-07"
        ixy="-9.73813296686781E-08"
        ixz="-3.43907565334525E-08"
        iyy="5.40139866980604E-07"
        iyz="1.94587609407361E-07"
        izz="3.84699652962392E-07" />
    </inertial>
    <visual>
      <origin
        xyz="0 0 0"
        rpy="0 0 0" />
      <geometry>
        <mesh
          filename="package://V4.SLDASM/meshes/LHIPy.STL" />
      </geometry>
      <material
        name="">
        <color
          rgba="0.792156862745098 0.819607843137255 0.933333333333333 1" />
      </material>
    </visual>
    <collision>
      <origin
        xyz="0 0 0"
        rpy="0 0 0" />
      <geometry>
        <mesh
          filename="package://V4.SLDASM/meshes/LHIPy.STL" />
      </geometry>
    </collision>
  </link>
  <joint
    name="LHIPy"
    type="revolute">
    <origin
      xyz="-0.032075 5.5879E-05 -6.6114E-05"
      rpy="0 0 0" />
    <parent
      link="LHIPp" />
    <child
      link="LHIPy" />
    <axis
      xyz="-0.001057 0 -1" />
    <limit
      lower="-0.14"
      upper="1.39"
      effort="0"
      velocity="0" />
  </joint>
  <link
    name="LHIPr">
    <inertial>
      <origin
        xyz="-0.000643093596794701 -0.0646139643461603 -0.00501142221648341"
        rpy="0 0 0" />
      <mass
        value="0.21670" />
      <inertia
        ixx="5.27058556255585E-06"
        ixy="4.82411876748749E-09"
        ixz="-1.90476290223497E-07"
        iyy="3.88872298790152E-06"
        iyz="1.83876643853407E-07"
        izz="5.30321916922738E-06" />
    </inertial>
    <visual>
      <origin
        xyz="0 0 0"
        rpy="0 0 0" />
      <geometry>
        <mesh
          filename="package://V4.SLDASM/meshes/LHIPr.STL" />
      </geometry>
      <material
        name="">
        <color
          rgba="0.792156862745098 0.819607843137255 0.933333333333333 1" />
      </material>
    </visual>
    <collision>
      <origin
        xyz="0 0 0"
        rpy="0 0 0" />
      <geometry>
        <mesh
          filename="package://V4.SLDASM/meshes/LHIPr.STL" />
      </geometry>
    </collision>
  </link>
  <joint
    name="LHIPr"
    type="fixed">
    <origin
      xyz="-0.006 -0.04714 0"
      rpy="-0.0063818 0.00081765 -0.035763" />
    <parent
      link="LHIPy" />
    <child
      link="LHIPr" />
    <axis
      xyz="0 0 0" />
    <limit
      lower="-1.47"
      upper="0.22"
      effort="0"
      velocity="0" />
  </joint>
  <link
    name="LKNEEp">
    <inertial>
      <origin
        xyz="-0.0109855620258126 -0.0393014331736789 -0.00773020940982851"
        rpy="0 0 0" />
      <mass
        value="0.13866" />
      <inertia
        ixx="5.89446081339765E-06"
        ixy="4.34439651059314E-08"
        ixz="4.87026069539692E-08"
        iyy="1.84730677092009E-06"
        iyz="-1.05630153101691E-08"
        izz="4.82704520180029E-06" />
    </inertial>
    <visual>
      <origin
        xyz="0 0 0"
        rpy="0 0 0" />
      <geometry>
        <mesh
          filename="package://V4.SLDASM/meshes/LKNEEp.STL" />
      </geometry>
      <material
        name="">
        <color
          rgba="0.792156862745098 0.819607843137255 0.933333333333333 1" />
      </material>
    </visual>
    <collision>
      <origin
        xyz="0 0 0"
        rpy="0 0 0" />
      <geometry>
        <mesh
          filename="package://V4.SLDASM/meshes/LKNEEp.STL" />
      </geometry>
    </collision>
  </link>
  <joint
    name="LKNEEp"
    type="revolute">
    <origin
      xyz="0.0033174 -0.09272 -0.00059902"
      rpy="0.020071 1.1667E-05 0.035763" />
    <parent
      link="LHIPr" />
    <child
      link="LKNEEp" />
    <axis
      xyz="1 0 0" />
    <limit
      lower="-2.26"
      upper="0.29"
      effort="0"
      velocity="0" />
  </joint>
  <link
    name="LANKLEp">
    <inertial>
      <origin
        xyz="-0.00350000178252131 -1.78252146376678E-09 1.78252139741361E-09"
        rpy="0 0 0" />
      <mass
        value="0.00289" />
      <inertia
        ixx="3.4783566292548E-08"
        ixy="9.19265220335925E-21"
        ixz="-9.17578258030457E-21"
        iyy="3.47835662925479E-08"
        iyz="-9.22187475783571E-21"
        izz="3.47835662925479E-08" />
    </inertial>
    <visual>
      <origin
        xyz="0 0 0"
        rpy="0 0 0" />
      <geometry>
        <mesh
          filename="package://V4.SLDASM/meshes/LANKLEp.STL" />
      </geometry>
      <material
        name="">
        <color
          rgba="0.776470588235294 0.756862745098039 0.737254901960784 1" />
      </material>
    </visual>
    <collision>
      <origin
        xyz="0 0 0"
        rpy="0 0 0" />
      <geometry>
        <mesh
          filename="package://V4.SLDASM/meshes/LANKLEp.STL" />
      </geometry>
    </collision>
  </link>
  <joint
    name="LANKLEp"
    type="revolute">
    <origin
      xyz="0 -0.14 0"
      rpy="0.0029502 0 0" />
    <parent
      link="LKNEEp" />
    <child
      link="LANKLEp" />
    <axis
      xyz="-1 0 0" />
    <limit
      lower="-1.04"
      upper="0.06"
      effort="0"
      velocity="0" />
  </joint>
  <link
    name="LANKLEy">
    <inertial>
      <origin
        xyz="-0.00349943343558675 -0.0174823136885467 -0.0244034793992341"
        rpy="0 0 0" />
      <mass
        value="0.02488" />
      <inertia
        ixx="5.0805809590663E-06"
        ixy="-2.23515300495595E-15"
        ixz="1.10261943482752E-14"
        iyy="6.07928686402194E-06"
        iyz="-2.76049804528687E-09"
        izz="1.17720026301645E-06" />
    </inertial>
    <visual>
      <origin
        xyz="0 0 0"
        rpy="0 0 0" />
      <geometry>
        <mesh
          filename="package://V4.SLDASM/meshes/LANKLEy.STL" />
      </geometry>
      <material
        name="">
        <color
          rgba="0.792156862745098 0.819607843137255 0.933333333333333 1" />
      </material>
    </visual>
    <collision>
      <origin
        xyz="0 0 0"
        rpy="0 0 0" />
      <geometry>
        <mesh
          filename="package://V4.SLDASM/meshes/LANKLEy.STL" />
      </geometry>
    </collision>
  </link>
  <joint
    name="LANKLEy"
    type="fixed">
    <origin
      xyz="0 0 0"
      rpy="0 0 -0.017993" />
    <parent
      link="LANKLEp" />
    <child
      link="LANKLEy" />
    <axis
      xyz="0 0 1" />
    <limit
      lower="-0.17"
      upper="0.17"
      effort="0"
      velocity="0" />
  </joint>
</robot>