<mujoco model="V4.SLDASM">
  <compiler angle="radian"/>

  <asset>
    <mesh name="base_link" file="base_link.STL"/>
    <mesh name="Waist" file="Waist.STL"/>
    <mesh name="Waist_2" file="Waist_2.STL"/>
    <mesh name="RSDp" file="RSDp.STL"/>
    <mesh name="RSDy" file="RSDy.STL"/>
    <mesh name="RSDr" file="RSDr.STL"/>
    <mesh name="RARMp" file="RARMp.STL"/>
    <mesh name="RARMAP" file="RARMAP.STL"/>
    <mesh name="RARMAy" file="RARMAy.STL"/>
    <mesh name="LSDp" file="LSDp.STL"/>
    <mesh name="LSDy" file="LSDy.STL"/>
    <mesh name="LSDr" file="LSDr.STL"/>
    <mesh name="LARMp" file="LARMp.STL"/>
    <mesh name="LARMAp" file="LARMAp.STL"/>
    <mesh name="LARMAy" file="LARMAy.STL"/>
    <mesh name="RHIPp" file="RHIPp.STL"/>
    <mesh name="RHIPy" file="RHIPy.STL"/>
    <mesh name="RHIPr" file="RHIPr.STL"/>
    <mesh name="RKNEEP" file="RKNEEP.STL"/>
    <mesh name="RANKLEp" file="RANKLEp.STL"/>
    <mesh name="RANKLEy" file="RANKLEy.STL"/>
    <mesh name="LHIPp" file="LHIPp.STL"/>
    <mesh name="LHIPy" file="LHIPy.STL"/>
    <mesh name="LHIPr" file="LHIPr.STL"/>
    <mesh name="LKNEEp" file="LKNEEp.STL"/>
    <mesh name="LANKLEp" file="LANKLEp.STL"/>
    <mesh name="LANKLEy" file="LANKLEy.STL"/>
  </asset>

  <worldbody>
    <geom type="mesh" rgba="0.792157 0.819608 0.933333 1" mesh="base_link"/>
    <geom pos="0.00275 0 0.04211" quat="0.707105 0.707108 0 0" type="mesh" rgba="1 1 1 1" mesh="Waist"/>
    <body name="Waist_2" pos="0.00275 -0.000670079 0.063715" quat="0.00105806 -0.00105806 -0.707102 -0.70711">
      <inertial pos="0.000488922 0.158905 -0.00145234" quat="0.0131414 0.723502 0.0112021 0.690106" mass="1.72647" diaginertia="0.00297215 0.00212529 0.00156505"/>
      <joint name="Waist_2" pos="0 0 0" axis="-0.00297029 -0.999996 0" range="-6.28 6.28"/>
      <geom type="mesh" rgba="0.792157 0.819608 0.933333 1" mesh="Waist_2"/>
      <body name="RSDp" pos="-0.081055 0.13392 0.003366" quat="-0.0267098 0.00245595 0.998995 0.0359158">
        <inertial pos="0.0293653 -0.0145377 -0.0120536" quat="0.76001 -0.0952301 -0.0619561 0.639904" mass="0.06956" diaginertia="6.86939e-06 6.51365e-06 1.92107e-06"/>
        <joint name="RSDp" pos="0 0 0" axis="1 0 0" range="-1.57 1.57"/>
        <geom type="mesh" rgba="0.792157 0.819608 0.933333 1" mesh="RSDp"/>
        <body name="RSDy" pos="0.047234 0.01 -0.00611">
          <inertial pos="0.0444263 -0.0611437 0.0269667" quat="0.122604 0.424866 -0.109066 0.89026" mass="0.58614" diaginertia="0.000103328 9.98335e-05 1.42266e-05"/>
          <joint name="RSDy" pos="0 0 0" axis="0 0.0717641 -0.997422" range="-1.39 0.14"/>
          <geom type="mesh" rgba="0.792157 0.819608 0.933333 1" mesh="RSDy"/>
          <geom pos="-0.0052192 -0.057271 0.0026804" quat="-0.000704089 0.0178865 -0.999077 -0.0390552" type="mesh" rgba="0.792157 0.819608 0.933333 1" mesh="RSDr"/>
          <body name="RARMp" pos="-0.00521558 -0.149649 -0.00395323" quat="1.17154e-07 1.9811e-05 -0.999356 -0.0358895">
            <inertial pos="-0.0109856 -0.0393014 -0.00773021" quat="0.705512 0.708315 -0.012254 0.0198132" mass="0.36176" diaginertia="1.53856e-05 1.25881e-05 4.81829e-06"/>
            <joint name="RARMp" pos="0 0 0" axis="1 0 0" range="-2.26 0.29"/>
            <geom type="mesh" rgba="0.792157 0.819608 0.933333 1" mesh="RARMp"/>
            <body name="RARMAP" pos="-0.0035 -0.14 0" quat="-0.0267808 3.77026e-06 -0.999641 -3.77026e-06">
              <inertial pos="-3.71919e-10 -0.0156065 0.0218638" quat="0.704053 0.065643 -0.065643 0.704053" mass="0.07245" diaginertia="2.05161e-05 1.94187e-05 4.67031e-06"/>
              <joint name="RARMAP" pos="0 0 0" axis="-0.998566 0 0.0535428" range="-0.06 1.04"/>
              <geom type="mesh" rgba="0.776471 0.756863 0.737255 1" mesh="RARMAP"/>
              <geom quat="0.999641 0 0.0267808 0" type="mesh" rgba="0.792157 0.819608 0.933333 1" mesh="RARMAy"/>
            </body>
          </body>
        </body>
      </body>
      <body name="LSDp" pos="0.085975 0.13342 -0.0055901" quat="-0.0262525 0.000297441 0.999655 5.40901e-05">
        <inertial pos="-0.0264851 -0.0161381 -0.0115557" quat="0.645694 0.0386131 0.12288 0.752654" mass="0.06956" diaginertia="6.84597e-06 6.46864e-06 1.89455e-06"/>
        <joint name="LSDp" pos="0 0 0" axis="0.999997 0.00238069 -0.001057" range="-1.57 1.57"/>
        <geom type="mesh" rgba="0.792157 0.819608 0.933333 1" mesh="LSDp"/>
        <body name="LSDy" pos="-0.031807 5.6518e-05 -6.6398e-05">
          <inertial pos="0.0292098 -0.0673207 -0.044134" quat="0.31069 0.859724 -0.0673382 0.399764" mass="0.58614" diaginertia="8.68955e-05 8.31168e-05 1.46597e-05"/>
          <joint name="LSDy" pos="0 0 0" axis="-0.001057 0 -0.999999" range="-0.14 1.39"/>
          <geom type="mesh" rgba="0.792157 0.819608 0.933333 1" mesh="LSDy"/>
          <geom pos="-0.006 -0.047115 0" quat="-0.000528291 1.52963e-05 0.999356 0.0358886" type="mesh" rgba="0.792157 0.819608 0.933333 1" mesh="LSDr"/>
          <body name="LARMp" pos="-0.00599932 -0.13992 2.99243e-06" quat="-0.0005285 -3.68202e-06 1 -1.66751e-05">
            <inertial pos="0.00720772 -0.037838 -0.00744236" quat="0.705471 0.708276 0.0139253 -0.021489" mass="0.36176" diaginertia="1.55169e-05 1.26528e-05 4.8858e-06"/>
            <joint name="LARMp" pos="0 0 0" axis="-1 0 0" range="-0.29 2.26"/>
            <geom type="mesh" rgba="0.792157 0.819608 0.933333 1" mesh="LARMp"/>
            <body name="LARMAp" pos="0 -0.14 0" quat="0.499998 0.5 -0.500002 -0.5">
              <inertial pos="3.76965e-10 -0.0156065 -0.0218638" quat="0.704053 -0.065643 0.065643 0.704053" mass="0.07245" diaginertia="2.05161e-05 1.94187e-05 4.67031e-06"/>
              <joint name="LARMAp" pos="0 0 0" axis="0 0 -1" range="-0.06 1.04"/>
              <geom type="mesh" rgba="0.776471 0.756863 0.737255 1" mesh="LARMAp"/>
              <geom quat="0.499998 -0.5 0.5 0.500002" type="mesh" rgba="0.792157 0.819608 0.933333 1" mesh="LARMAy"/>
            </body>
          </body>
        </body>
      </body>
    </body>
    <body name="RHIPp" pos="0.017714 0 0" quat="0.73203 0.681273 0 0">
      <inertial pos="0.0295665 -0.0145377 -0.0120536" quat="0.76001 -0.0952301 -0.0619561 0.639904" mass="0.06956" diaginertia="6.86939e-06 6.51365e-06 1.92107e-06"/>
      <joint name="RHIPp" pos="0 0 0" axis="-1 0 0" range="-1.57 1.57"/>
      <geom type="mesh" rgba="0.792157 0.819608 0.933333 1" mesh="RHIPp"/>
      <body name="RHIPy" pos="0.047436 0.01 -0.00611">
        <inertial pos="0.0370318 -0.0707943 -0.0498001" quat="0.251761 0.897327 -0.0133578 0.362274" mass="0.58614" diaginertia="9.68788e-05 9.24512e-05 1.45355e-05"/>
        <joint name="RHIPy" pos="0 0 0" axis="0 0.0717641 -0.997422" range="-1.39 0.14"/>
        <geom type="mesh" rgba="0.792157 0.819608 0.933333 1" mesh="RHIPy"/>
        <geom pos="-0.0052192 -0.057244 0.0026823" quat="1 0 0 0" type="mesh" rgba="0.792157 0.819608 0.933333 1" mesh="RHIPr"/>
        <body name="RKNEEP" pos="-0.0052192 -0.149647 -0.003966" quat="0.999392 0.0348704 0 0">
          <inertial pos="0.00720772 -0.037838 -0.00744236" quat="0.705471 0.708276 0.0139253 -0.021489" mass="0.36176" diaginertia="1.55169e-05 1.26528e-05 4.8858e-06"/>
          <joint name="RKNEEP" pos="0 0 0" axis="-1 0 0" range="-0.29 2.26"/>
          <geom type="mesh" rgba="0.792157 0.819608 0.933333 1" mesh="RKNEEP"/>
          <body name="RANKLEp" pos="0 -0.14 0">
            <inertial pos="4.38951e-09 -0.0156065 -0.0218638" quat="0.704053 -0.0656429 0.0656429 0.704053" mass="0.07245" diaginertia="2.05161e-05 1.94187e-05 4.67031e-06"/>
            <joint name="RANKLEp" pos="0 0 0" axis="-1 0 0" range="-1.04 0.06"/>
            <geom type="mesh" rgba="0.776471 0.756863 0.737255 1" mesh="RANKLEp"/>
            <geom quat="1 0 0 -4.8388e-05" type="mesh" rgba="0.792157 0.819608 0.933333 1" mesh="RANKLEy"/>
          </body>
        </body>
      </body>
    </body>
    <body name="LHIPp" pos="-0.022372 0 0" quat="0.707104 0.707108 0.000467996 -0.00121541">
      <inertial pos="-0.0267535 -0.0161387 -0.0115554" quat="0.645694 0.0386131 0.12288 0.752654" mass="0.06956" diaginertia="6.84597e-06 6.46864e-06 1.89455e-06"/>
      <joint name="LHIPp" pos="0 0 0" axis="0.999997 0.00238069 -0.001057" range="-1.57 1.57"/>
      <geom type="mesh" rgba="0.792157 0.819608 0.933333 1" mesh="LHIPp"/>
      <body name="LHIPy" pos="-0.032075 5.5879e-05 -6.6114e-05">
        <inertial pos="0.0372676 -0.0594718 0.0196223" quat="0.17088 0.440977 -0.150567 0.868141" mass="0.58614" diaginertia="0.000101549 9.79848e-05 1.39597e-05"/>
        <joint name="LHIPy" pos="0 0 0" axis="-0.001057 0 -0.999999" range="-0.14 1.39"/>
        <geom type="mesh" rgba="0.792157 0.819608 0.933333 1" mesh="LHIPy"/>
        <geom pos="-0.006 -0.04714 0" quat="0.999835 -0.00318307 0.000465812 -0.0178792" type="mesh" rgba="0.792157 0.819608 0.933333 1" mesh="LHIPr"/>
        <body name="LKNEEp" pos="-0.00600004 -0.139921 -1.00038e-05" quat="0.999976 0.0068612 0.000528473 -4.0176e-06">
          <inertial pos="-0.0109856 -0.0393014 -0.00773021" quat="0.705512 0.708315 -0.012254 0.0198132" mass="0.36176" diaginertia="1.53856e-05 1.25881e-05 4.81829e-06"/>
          <joint name="LKNEEp" pos="0 0 0" axis="1 0 0" range="-2.26 0.29"/>
          <geom type="mesh" rgba="0.792157 0.819608 0.933333 1" mesh="LKNEEp"/>
          <body name="LANKLEp" pos="0 -0.14 0" quat="0.999999 0.0014751 0 0">
            <inertial pos="-0.00349949 -0.0156629 -0.0218638" quat="0.704043 -0.0659218 0.0659139 0.704012" mass="0.07245" diaginertia="2.05204e-05 1.94336e-05 4.68087e-06"/>
            <joint name="LANKLEp" pos="0 0 0" axis="-1 0 0" range="-1.04 0.06"/>
            <geom type="mesh" rgba="0.776471 0.756863 0.737255 1" mesh="LANKLEp"/>
            <geom quat="0.99996 0 0 -0.00899638" type="mesh" rgba="0.792157 0.819608 0.933333 1" mesh="LANKLEy"/>
          </body>
        </body>
      </body>
    </body>
  </worldbody>
</mujoco>
